Workbook

Sheet ANTIPASTI
B1: GASTRONOMIA NATALE 2023
B2: ANTIPASTI
B3: N ORDINE | C3: SALMONE MARINATO (N. PORZIONI) | D3: POLPO MEDITERRANEA (N. PORZIONI) | E3: POLPO E PATATE (N. PORZIONI) | F3: INSALATA DI MARE (N. PORZIONI) | G3: INSALATA RUSSA CON GAMBERI (N. PORZIONI) | H3: COCKTAIL GAMBERI (N. PORZIONI) | I3: INSALATA BACCALA' (N. PORZIONI) | J3: GAMBERI ALLA CATALANA (N. PORZIONI) | K3: FLAN CAPESANTE (N. PEZZI) | L3: BRIOCHE SALMONE (N. PEZZI) | M3: POLENTA E MOSCARDINI (N. PEZZI) | N3: GAMBERI PASTA KATAIFI (N.PEZZI) | O3: PANETTONE GASTRO (N. PEZZI) | P3: ARAGOSTA IN BELLAVISTA (N.MEZZA) | Q3: MOSCARDINI UMIDO | R3: EXTRA X EMERGENZA
B4: 100 | C4: 0 | D4: 0 | E4: 10 | F4: 0 | G4: 0 | H4: 10 | I4: 0 | J4: 10 | K4: 0 | L4: 0 | M4: 0 | N4: 0 | O4: 0 | P4: 0 | Q4: 0 | R4: 0
B5: 101 | C5: 0 | D5: 0 | E5: 0 | F5: 0 | G5: 0 | H5: 0 | I5: 0 | J5: 0 | K5: 0 | L5: 0 | M5: 0 | N5: 0 | O5: 0 | P5: 0 | Q5: 0 | R5: 0
B6: 102 | C6: 0 | D6: 0 | E6: 1 | F6: 0 | G6: 0 | H6: 0 | I6: 8 | J6: 0 | K6: 0 | L6: 0 | M6: 8 | N6: 3 | O6: 0 | P6: 0 | Q6: 0 | R6: 0
B7: 103 | C7: 0 | D7: 0 | E7: 0 | F7: 4 | G7: 0 | H7: 0 | I7: 0 | J7: 0 | K7: 0 | L7: 0 | M7: 0 | N7: 0 | O7: 0 | P7: 0 | Q7: 0 | R7: 0
B8: 104 | C8: 0 | D8: 0 | E8: 0 | F8: 0 | G8: 0 | H8: 0 | I8: 0 | J8: 0 | K8: 0 | L8: 0 | M8: 0 | N8: 0 | O8: 0 | P8: 0 | Q8: 0 | R8: 0
B9: 105 | C9: 0 | D9: 3 | E9: 0 | F9: 0 | G9: 0 | H9: 0 | I9: 2 | J9: 4 | K9: 0 | L9: 0 | M9: 0 | N9: 0 | O9: 0 | P9: 0 | Q9: 0 | R9: 0
B10: 106 | C10: 0 | D10: 1 | E10: 0 | F10: 0 | G10: 0 | H10: 0 | I10: 0 | J10: 0 | K10: 0 | L10: 0 | M10: 0 | N10: 0 | O10: 0 | P10: 0 | Q10: 0 | R10: 0
B11: 107 | C11: 0 | D11: 0 | E11: 0 | F11: 0 | G11: 0 | H11: 0 | I11: 4 | J11: 0 | K11: 4 | L11: 0 | M11: 0 | N11: 0 | O11: 0 | P11: 0 | Q11: 0 | R11: 0
B12: 108 | C12: 0 | D12: 0 | E12: 2 | F12: 0 | G12: 0 | H12: 0 | I12: 2 | J12: 0 | K12: 0 | L12: 0 | M12: 0 | N12: 0 | O12: 0 | P12: 0 | Q12: 0 | R12: 0
B13: 109 | C13: 0 | D13: 5 | E13: 0 | F13: 0 | G13: 5 | H13: 0 | I13: 0 | J13: 0 | K13: 0 | L13: 0 | M13: 8 | N13: 0 | O13: 0 | P13: 0 | Q13: 0 | R13: 0
B14: 110 | C14: 2 | D14: 0 | E14: 0 | F14: 0 | G14: 0 | H14: 0 | I14: 0 | J14: 0 | K14: 0 | L14: 0 | M14: 0 | N14: 0 | O14: 0 | P14: 0 | Q14: 0 | R14: 0
B15: 111 | C15: 2 | D15: 2 | E15: 2 | F15: 0 | G15: 2 | H15: 0 | I15: 2 | J15: 2 | K15: 0 | L15: 0 | M15: 0 | N15: 0 | O15: 0 | P15: 0 | Q15: 0 | R15: 0
... B81: 177 | C81: 0 | D81: 0 | E81: 0 | F81: 0 | G81: 0 | H81: 0 | I81: 0 | J81: 0 | K81: 0 | L81: 0 | M81: 0 | N81: 0 | O81: 0 | P81: 0 | Q81: 0 | R81: 0
B82: 178 | C82: 0 | D82: 0 | E82: 0 | F82: 3 | G82: 0 | H82: 0 | I82: 2 | J82: 0 | K82: 2 | L82: 0 | M82: 2 | N82: 0 | P82: 0 | Q82: 0 | R82: 0
B83: 179 | C83: 0 | D83: 0 | E83: 0 | F83: 0 | G83: 0 | H83: 4 | I83: 0 | J83: 0 | K83: 0 | L83: 0 | M83: 0 | N83: 0 | O83: 0 | P83: 0 | Q83: 0 | R83: 0
B84: 180 | C84: 0 | D84: 0 | E84: 0 | F84: 0 | G84: 0 | H84: 0 | I84: 0 | J84: 0 | K84: 0 | L84: 3 | M84: 0 | N84: 0 | O84: 1 | P84: 0 | Q84: 0 | R84: 0
B85: 181 | C85: 0 | D85: 3 | E85: 3 | F85: 0 | G85: 0 | H85: 0 | I85: 0 | J85: 0 | K85: 0 | L85: 0 | M85: 0 | N85: 0 | O85: 0 | P85: 0 | Q85: 0 | R85: 0
B86: 182 | C86: 0 | D86: 0 | E86: 3 | F86: 0 | G86: 0 | H86: 2 | I86: 0 | J86: 0 | K86: 0 | L86: 0 | M86: 0 | N86: 0 | O86: 0 | P86: 0 | Q86: 0 | R86: 0
B87: 183 | C87: 0 | D87: 0 | E87: 2 | F87: 0 | G87: 0 | H87: 2 | I87: 2 | J87: 0 | K87: 0 | L87: 0 | M87: 0 | N87: 10 | O87: 0 | P87: 7 | Q87: 0 | R87: 0
B88: 184 | C88: 2 | D88: 3 | E88: 0 | F88: 2 | G88: 0 | H88: 3 | I88: 0 | J88: 2 | K88: 0 | L88: 5 | M88: 2 | N88: 0 | O88: 0 | P88: 0 | Q88: 0 | R88: 0
B89: 185 | C89: 0 | D89: 0 | E89: 0 | F89: 3 | G89: 0 | H89: 0 | I89: 0 | J89: 0 | K89: 0 | L89: 0 | M89: 0 | N89: 0 | O89: 0 | P89: 0 | Q89: 0 | R89: 0
B90: 186 | C90: 0 | D90: 4 | E90: 4 | F90: 0 | G90: 0 | H90: 0 | I90: 0 | J90: 3 | K90: 0 | L90: 0 | M90: 3 | N90: 0 | O90: 0 | P90: 0 | Q90: 0 | R90: 0
B91: 187 | C91: 0 | D91: 0 | E91: 0 | F91: 0 | G91: 0 | H91: 0 | I91: 0 | J91: 0 | K91: 6 | L91: 6 | M91: 0 | N91: 6 | O91: 0 | P91: 0 | Q91: 0 | R91: 0
B92: 188 | C92: 0 | D92: 0 | E92: 0 | F92: 0 | G92: 0 | H92: 12 | I92: 0 | J92: 0 | K92: 0 | L92: 0 | M92: 0 | N92: 0 | O92: 0 | P92: 0 | Q92: 0 | R92: 0
B93: 189 | C93: 0 | D93: 0 | E93: 0 | F93: 4 | G93: 3 | H93: 2 | I93: 0 | J93: 0 | K93: 0 | L93: 0 | M93: 0 | N93: 4 | O93: 0 | P93: 0 | Q93: 0 | R93: 0
B94: 190 | C94: 2 | D94: 0 | E94: 0 | F94: 0 | G94: 0 | H94: 0 | I94: 0 | J94: 0 | K94: 0 | L94: 0 | M94: 0 | N94: 0 | O94: 0 | P94: 0 | Q94: 0 | R94: 0
... B180: 276 | C180: 0 | D180: 0 | E180: 0 | F180: 3 | G180: 0 | H180: 0 | I180: 0 | J180: 0 | K180: 0 | L180: 0 | M180: 0 | N180: 0 | O180: 0 | P180: 0 | Q180: 0 | R180: 0
B181: 277
B182: 278
B183: 279
B184: 280
B185: 281
B186: 282
B187: 283
B188: 284
B189: 285
B190: 286
...

Sheet CRUDI
A1: GASTRONOMIA NATALE 2023
B2: CRUDI
B3: N ORDINE | C3: SELEZIONE TARTARE (N. PIATTI) | D3: MAREMIO CARPACCI x 1(N VASCHETTE) | E3: TARTARE TONNO 120 GR (N. PEZZI) | F3: TARTARE SALMONE 120GR (N. PEZZI) | G3: TARTARE ORATA 120 GR (N. PEZZI) | H3: TARTARE BRANZINO 120 GR (N. PEZZI) | I3: CARPACCIO TONNO 100GR | J3: CAPASANTA CARPACCIO | K3: MAREMIO CARPACCI X1 NO CROSTACEI | L3: EXTRA X EMERGENZA | M3: EXTRA X EMERGENZA
B4: 100 | C4: 0 | D4: 0 | E4: 0 | F4: 0 | G4: 0 | H4: 0 | I4: 0 | J4: 0 | K4: 0 | L4: 0 | M4: 0
B5: 101 | C5: 0 | D5: 0 | E5: 4 | F5: 0 | G5: 0 | H5: 0 | I5: 4 | J5: 0 | K5: 0 | L5: 0 | M5: 0
B6: 102 | C6: 0 | D6: 0 | E6: 0 | F6: 0 | G6: 0 | H6: 0 | I6: 0 | J6: 0 | K6: 0 | L6: 0 | M6: 0
B7: 103 | C7: 0 | D7: 0 | E7: 0 | F7: 0 | G7: 0 | H7: 0 | I7: 0 | J7: 0 | K7: 0 | L7: 0 | M7: 0
B8: 104 | C8: 0 | D8: 0 | E8: 0 | F8: 0 | G8: 0 | H8: 0 | I8: 0 | J8: 0 | K8: 0 | L8: 0 | M8: 0
B9: 105 | C9: 0 | D9: 0 | E9: 0 | F9: 0 | G9: 0 | H9: 0 | I9: 0 | J9: 0 | K9: 0 | L9: 0 | M9: 0
B10: 106 | C10: 0 | D10: 0 | E10: 0 | F10: 0 | G10: 0 | H10: 0 | I10: 0 | J10: 0 | K10: 0 | L10: 0 | M10: 0
B11: 107 | C11: 0 | D11: 0 | E11: 0 | F11: 0 | G11: 0 | H11: 0 | I11: 0 | J11: 0 | K11: 0 | L11: 0 | M11: 0
B12: 108 | C12: 0 | D12: 0 | E12: 0 | F12: 0 | G12: 0 | H12: 0 | I12: 0 | J12: 0 | K12: 0 | L12: 0 | M12: 0
B13: 109 | C13: 0 | D13: 0 | E13: 0 | F13: 0 | G13: 0 | H13: 0 | I13: 0 | J13: 0 | K13: 0 | L13: 0 | M13: 0
B14: 110 | C14: 0 | D14: 0 | E14: 0 | F14: 0 | G14: 0 | H14: 0 | I14: 0 | J14: 0 | K14: 0 | L14: 0 | M14: 0
B15: 111 | C15: 0 | D15: 0 | E15: 0 | F15: 0 | G15: 0 | H15: 0 | I15: 0 | J15: 0 | K15: 0 | L15: 0 | M15: 0
... B169: 265 | C169: 0 | D169: 0 | E169: 0 | F169: 0 | G169: 0 | H169: 0 | I169: 0 | J169: 0 | K169: 0 | L169: 0 | M169: 0
B170: 266 | C170: 0 | D170: 0 | F170: 0 | G170: 0 | H170: 0 | I170: 0 | J170: 0 | K170: 0 | L170: 0 | M170: 0
B171: 267 | C171: 0 | D171: 0 | E171: 0 | F171: 0 | G171: 0 | H171: 0 | I171: 0 | J171: 0 | K171: 0 | L171: 0 | M171: 0
B172: 268 | C172: 0 | D172: 0 | E172: 0 | F172: 0 | G172: 0 | H172: 0 | I172: 0 | J172: 0 | K172: 0 | L172: 0 | M172: 0
B173: 269 | C173: 0 | D173: 0 | E173: 0 | F173: 0 | G173: 0 | H173: 0 | I173: 0 | J173: 0 | K173: 0 | L173: 0 | M173: 0
B174: 270 | C174: 0 | D174: 0 | E174: 0 | F174: 0 | G174: 0 | H174: 0 | I174: 0 | J174: 0 | K174: 0 | L174: 0 | M174: 0
B175: 271 | C175: 0 | D175: 0 | E175: 0 | F175: 0 | G175: 0 | H175: 0 | I175: 0 | J175: 0 | K175: 0 | L175: 0 | M175: 0
B176: 272 | C176: 0 | D176: 1 | E176: 0 | F176: 0 | G176: 0 | H176: 0 | I176: 0 | J176: 0 | K176: 0 | L176: 0 | M176: 0
B177: 273 | C177: 0 | D177: 0 | E177: 0 | F177: 1 | G177: 0 | H177: 0 | I177: 0 | J177: 0 | K177: 0 | L177: 0 | M177: 0
B178: 274 | C178: 0 | D178: 9 | E178: 0 | F178: 0 | G178: 0 | H178: 0 | I178: 0 | J178: 0 | K178: 0 | L178: 0 | M178: 0
B179: 275 | C179: 0 | D179: 0 | E179: 0 | F179: 0 | G179: 0 | H179: 0 | I179: 0 | J179: 0 | K179: 0 | L179: 0 | M179: 0
B180: 276 | C180: 0 | D180: 0 | E180: 0 | F180: 0 | G180: 0 | H180: 0 | I180: 0 | J180: 0 | K180: 0 | L180: 0 | M180: 0
B181: 277
B182: 278
B183: 279
B184: 280
B185: 281
B186: 282
B187: 283
B188: 284
B189: 285
B190: 286
B191: 287
B192: 288
... B200: 296
...

Sheet PRIMI
A1: GASTRONOMIA NATALE 2023
B2: PRIMI E PRONTI A CUOCERE
B3: N ORDINE | C3: LASAGNA MAZZANCOLLE, RADICCHIO E SCAMORZA (N. VASCHETTE) | D3: CRESPELLE GAMBERI E ZUCCHINE (N. VASCHETTE) | E3: LASAGNA BRANZINO E CARCIOFI (N. VASCHETTE) | F3: CANNELLONI SALMONE E RICOTTA (N. VASCHETTE) | G3: CAPASANTA GRATINATA (N. PEZZI) | H3: LASAGNE RAGU' DI MARE (N. VASCHETTE)
B4: 100 | C4: 0 | D4: 0 | E4: 0 | F4: 0 | G4: 0 | H4: 0
B5: 101 | C5: 0 | D5: 0 | E5: 0 | F5: 0 | G5: 0 | H5: 0
B6: 102 | C6: 0 | D6: 8 | E6: 0 | F6: 0 | G6: 0 | H6: 0
B7: 103 | C7: 0 | D7: 0 | E7: 0 | F7: 0 | G7: 0 | H7: 0
B8: 104 | C8: 1 | D8: 0 | E8: 0 | F8: 0 | G8: 0 | H8: 0
B9: 105 | C9: 0 | D9: 0 | E9: 0 | F9: 0 | G9: 0 | H9: 0
B10: 106 | C10: 1 | D10: 0 | E10: 0 | F10: 0 | G10: 0 | H10: 0
B11: 107 | C11: 0 | D11: 0 | E11: 0 | F11: 0 | G11: 0 | H11: 0
B12: 108 | C12: 0 | D12: 0 | E12: 0 | F12: 0 | G12: 0 | H12: 0
B13: 109 | C13: 4 | D13: 0 | E13: 0 | F13: 0 | G13: 0 | H13: 0
B14: 110 | C14: 4 | D14: 0 | E14: 3 | F14: 0 | G14: 0 | H14: 0
B15: 111 | C15: 2 | D15: 2 | E15: 0 | F15: 0 | G15: 0 | H15: 0
... B51: 147 | C51: 0 | D51: 0 | E51: 0 | F51: 0 | G51: 0 | H51: 0
B52: 148 | C52: 1 | D52: 0 | E52: 0 | F52: 0 | G52: 6
B53: 149 | C53: 2 | D53: 0 | E53: 0 | F53: 0 | G53: 0 | H53: 0
B54: 150 | C54: 0 | D54: 0 | E54: 0 | F54: 0 | G54: 0 | H54: 0
B55: 151 | C55: 0 | D55: 0 | E55: 0 | F55: 0 | G55: 0 | H55: 0
B56: 152 | C56: 0 | D56: 1 | E56: 0 | F56: 0 | G56: 0 | H56: 0
B57: 153 | C57: 0 | D57: 0 | E57: 1 | F57: 1 | G57: 0 | H57: 0
B58: 154 | C58: 0 | D58: 0 | E58: 0 | F58: 0 | G58: 0 | H58: 0
B59: 155 | C59: 0 | D59: 0 | E59: 0 | F59: 0 | G59: 0 | H59: 0
B60: 156 | C60: 1 | D60: 0 | E60: 0 | F60: 0 | G60: 0 | H60: 0
B61: 157 | C61: 2 | D61: 2 | E61: 2 | F61: 0 | G61: 0 | H61: 0
B62: 158 | C62: 0 | D62: 0 | E62: 0 | F62: 0 | G62: 0 | H62: 0
B63: 159 | C63: 0 | D63: 6 | E63: 0 | F63: 0 | G63: 0 | H63: 0
B64: 160 | C64: 0 | D64: 0 | E64: 1 | F64: 0 | G64: 0 | H64: 0
... B180: 276 | C180: 0 | D180: 0 | E180: 0 | F180: 0 | G180: 0 | H180: 0
B181: 277
B182: 278
B183: 279
B184: 280
B185: 281
B186: 282
B187: 283
B188: 284
B189: 285
B190: 286
...

Sheet SUGHI
A1: GASTRONOMIA NATALE 2023
B2: SUGHI PRONTI
B3: N ORDINE | C3: SUGO ASTICE MEZZO (N. PORZIONI) | D3: RAGU' DI GALLINELLA (N. PORZIONI) | E3: PESTO PISTACCHI E GAMBERI (N. PORZIONI) | F3: SUGO ALLA PESCATORA (N. PORZIONI) | G3: EXTRA X EMERGENZA | H3: EXTRA X EMERGENZA
B4: 100 | C4: 0 | D4: 0 | E4: 0 | F4: 0 | G4: 0 | H4: 0
B5: 101 | C5: 0 | D5: 0 | E5: 0 | F5: 0 | G5: 0 | H5: 0
B6: 102 | C6: 0 | D6: 0 | E6: 0 | F6: 0 | G6: 0 | H6: 0
B7: 103 | C7: 0 | D7: 0 | E7: 0 | F7: 0 | G7: 0 | H7: 0
B8: 104 | C8: 0 | D8: 0 | E8: 0 | F8: 0 | G8: 0 | H8: 0
B9: 105 | C9: 0 | D9: 4 | E9: 0 | F9: 0 | G9: 0 | H9: 0
B10: 106 | C10: 0 | D10: 0 | E10: 0 | F10: 0 | G10: 0 | H10: 0
B11: 107 | C11: 0 | D11: 4 | E11: 0 | F11: 0 | G11: 0 | H11: 0
B12: 108 | C12: 3 | D12: 0 | E12: 0 | F12: 0 | G12: 0 | H12: 0
B13: 109 | C13: 0 | D13: 2 | E13: 2 | F13: 0 | G13: 0 | H13: 0
B14: 110 | C14: 0 | D14: 0 | E14: 0 | F14: 2 | G14: 0 | H14: 0
B15: 111 | C15: 0 | D15: 4 | E15: 0 | F15: 0 | G15: 0 | H15: 0
... B180: 276 | C180: 3 | D180: 0 | E180: 0 | F180: 0 | G180: 0 | H180: 0
B181: 277
B182: 278
B183: 279
B184: 280
B185: 281
B186: 282
B187: 283
B188: 284
B189: 285
B190: 286
B191: 287
B192: 288
... B201: 297
A202: TOTALE | C202: =SUM(C4:C201) -> 79 | D202: =SUM(D4:D201) -> 26 | E202: =SUM(E4:E201) -> 18 | F202: =SUM(F4:F201) -> 69 | G202: =SUM(G4:G201) -> 0 | H202: =SUM(H4:H201) -> 0
A203: X | B203: 1 | C203: =COUNTIF($C$4:$C$201, $B203) -> 0 | D203: =COUNTIF($D$4:$D$201, $B203) -> 1 | E203: =COUNTIF($E$4:$E$201, $B203) -> 1 | F203: =COUNTIF($F$4:$F$201, $B203) -> 0 | G203: =COUNTIF($G$4:$G$201, $B203) -> 0 | H203: =COUNTIF($H$4:$H$201, $B203) -> 0
A204: X | B204: 2 | C204: =COUNTIF($C$4:$C$201, $B204) -> 6 | D204: =COUNTIF($D$4:$D$201, $B204) -> 2 | E204: =COUNTIF($E$4:$E$201, $B204) -> 2 | F204: =COUNTIF($F$4:$F$201, $B204) -> 3 | G204: =COUNTIF($G$4:$G$201, $B204) -> 0 | H204: =COUNTIF($H$4:$H$201, $B204) -> 0
A205: X | B205: 3 | C205: =COUNTIF($C$4:$C$201, $B205) -> 7 | D205: =COUNTIF($D$4:$D$201, $B205) -> 0 | E205: =COUNTIF($E$4:$E$201, $B205) -> 1 | F205: =COUNTIF($F$4:$F$201, $B205) -> 1 | G205: =COUNTIF($G$4:$G$201, $B205) -> 0 | H205: =COUNTIF($H$4:$H$201, $B205) -> 0
A206: X | B206: 4 | C206: =COUNTIF($C$4:$C$201, $B206) -> 2 | D206: =COUNTIF($D$4:$D$201, $B206) -> 4 | E206: =COUNTIF($E$4:$E$201, $B206) -> 0 | F206: =COUNTIF($F$4:$F$201, $B206) -> 1 | G206: =COUNTIF($G$4:$G$201, $B206) -> 0 | H206: =COUNTIF($H$4:$H$201, $B206) -> 0
A207: X | B207: 5 | C207: =COUNTIF($C$4:$C$201, $B207) -> 3 | D207: =COUNTIF($D$4:$D$201, $B207) -> 1 | E207: =COUNTIF($E$4:$E$201, $B207) -> 2 | F207: =COUNTIF($F$4:$F$201, $B207) -> 5 | G207: =COUNTIF($G$4:$G$201, $B207) -> 0 | H207: =COUNTIF($H$4:$H$201, $B207) -> 0
A208: X | B208: 6 | C208: =COUNTIF($C$4:$C$201, $B208) -> 0 | D208: =COUNTIF($D$4:$D$201, $B208) -> 0 | E208: =COUNTIF($E$4:$E$201, $B208) -> 0 | F208: =COUNTIF($F$4:$F$201, $B208) -> 1 | G208: =COUNTIF($G$4:$G$201, $B208) -> 0 | H208: =COUNTIF($H$4:$H$201, $B208) -> 0
A209: X | B209: 7 | C209: =COUNTIF($C$4:$C$201, $B209) -> 1 | D209: =COUNTIF($D$4:$D$201, $B209) -> 0 | E209: =COUNTIF($E$4:$E$201, $B209) -> 0 | F209: =COUNTIF($F$4:$F$201, $B209) -> 0 | G209: =COUNTIF($G$4:$G$201, $B209) -> 0 | H209: =COUNTIF($H$4:$H$201, $B209) -> 0
A210: X | B210: 8 | C210: =COUNTIF($C$4:$C$201, $B210) -> 2 | D210: =COUNTIF($D$4:$D$201, $B210) -> 0 | E210: =COUNTIF($E$4:$E$201, $B210) -> 0 | F210: =COUNTIF($F$4:$F$201, $B210) -> 2 | G210: =COUNTIF($G$4:$G$201, $B210) -> 0 | H210: =COUNTIF($H$4:$H$201, $B210) -> 0
A211: X | B211: 9 | C211: =COUNTIF($C$4:$C$201, $B211) -> 0 | D211: =COUNTIF($D$4:$D$201, $B211) -> 0 | E211: =COUNTIF($E$4:$E$201, $B211) -> 0 | F211: =COUNTIF($F$4:$F$201, $B211) -> 1 | G211: =COUNTIF($G$4:$G$201, $B211) -> 0 | H211: =COUNTIF($H$4:$H$201, $B211) -> 0
A212: X | B212: 10 | C212: =COUNTIF($C$4:$C$201, $B212) -> 0 | D212: =COUNTIF($D$4:$D$201, $B212) -> 0 | E212: =COUNTIF($E$4:$E$201, $B212) -> 0 | F212: =COUNTIF($F$4:$F$201, $B212) -> 0 | G212: =COUNTIF($G$4:$G$201, $B212) -> 0 | H212: =COUNTIF($H$4:$H$201, $B212) -> 0
...

Sheet SECONDI 
A1: GASTRONOMIA NATALE 2023
B2: SECONDI PIATTI
B3: N ORDINE | C3: SPIEDINI BRANZINO GRATINATI (N. PEZZI) | D3: ORATA IN CROSTA (N. PEZZI) | E3: BACCALA' FRITTO (N. PORZIONI) | F3: BRANZINO IN CROSTA (N. PEZZI) | G3: SALMONE AL LIMONE (N. PEZZI) | H3: EXTRA X EMERGENZA
B4: 100 | C4: 0 | D4: 0 | E4: 0 | F4: 0 | G4: 0 | H4: 0
B5: 101 | C5: 0 | D5: 0 | E5: 0 | F5: 0 | G5: 0 | H5: 0
B6: 102 | C6: 1 | D6: 8 | E6: 0 | F6: 0 | G6: 0 | H6: 0
B7: 103 | C7: 0 | D7: 0 | E7: 0 | F7: 0 | G7: 0 | H7: 0
B8: 104 | C8: 0 | D8: 2 | E8: 0 | F8: 2 | G8: 0 | H8: 0
B9: 105 | C9: 0 | D9: 0 | E9: 0 | F9: 0 | G9: 0 | H9: 0
B10: 106 | C10: 0 | D10: 1 | E10: 0 | F10: 1 | G10: 0 | H10: 0
B11: 107 | C11: 0 | D11: 4 | E11: 0 | F11: 0 | G11: 0 | H11: 0
B12: 108 | C12: 0 | D12: 0 | E12: 0 | F12: 0 | G12: 0 | H12: 0
B13: 109 | C13: 0 | D13: 0 | E13: 0 | F13: 0 | G13: 0 | H13: 0
B14: 110 | C14: 0 | D14: 0 | E14: 0 | F14: 0 | G14: 0 | H14: 0
B15: 111 | C15: 3 | D15: 0 | E15: 0 | F15: 2 | G15: 0 | H15: 0
... B171: 267 | C171: 6 | D171: 0 | E171: 0 | F171: 0 | G171: 0 | H171: 0
B172: 268 | C172: 0 | D172: 0 | E172: 2 | F172: 0 | G172: 0
B173: 269 | C173: 0 | D173: 0 | E173: 0 | F173: 0 | G173: 0 | H173: 0
B174: 270 | C174: 0 | D174: 0 | E174: 0 | F174: 0 | G174: 0 | H174: 0
B175: 271 | C175: 0 | D175: 0 | E175: 0 | F175: 0 | G175: 0 | H175: 0
B176: 272 | C176: 0 | D176: 0 | E176: 0 | F176: 0 | G176: 0 | H176: 0
B177: 273 | C177: 0 | D177: 0 | E177: 0 | F177: 0 | G177: 0 | H177: 0
B178: 274 | C178: 0 | D178: 0 | E178: 0 | F178: 0 | G178: 0 | H178: 0
B179: 275 | C179: 0 | D179: 0 | E179: 0 | F179: 0 | G179: 0 | H179: 0
B180: 276 | C180: 0 | D180: 0 | E180: 0 | F180: 0 | G180: 0 | H180: 0
B181: 277
B182: 278
B183: 279
B184: 280
B185: 281
B186: 282
B187: 283
B188: 284
B189: 285
B190: 286
B191: 287
B192: 288
... B201: 297
A202: TOTALE | C202: =SUM(C4:C201) -> 119 | D202: =SUM(D4:D201) -> 83 | E202: =SUM(E4:E201) -> 21 | F202: =SUM(F4:F201) -> 23 | G202: =SUM(G4:G201) -> 3 | H202: =SUM(H4:H201) -> 0
A203: X | B203: 1 | C203: =COUNTIF($C$4:$C$201, $B203) -> 3 | D203: =COUNTIF($D$4:$D$201, $B203) -> 6 | E203: =COUNTIF($E$4:$E$201, $B203) -> 3 | F203: =COUNTIF($F$4:$F$201, $B203) -> 4 | G203: =COUNTIF($G$4:$G$201, $B203) -> 1 | H203: =COUNTIF($H$4:$H$201, $B203) -> 0
...

Sheet SALMONE MARINATO
A1: SALMONE MARINATO (DIVISIONE IN PORZIONI)
A4: X 1 | B4: =ANTIPASTI!C207 -> 8 | C4: =1*B4 -> 8
A5: X 2 | B5: =ANTIPASTI!C208 -> 12 | C5: =2*B5 -> 24
A6: X 3 | B6: =ANTIPASTI!C209 -> 4 | C6: =3*B6 -> 12
A7: X 4 | B7: =ANTIPASTI!C210 -> 2 | C7: =4*B7 -> 8
A8: X 5 | B8: =ANTIPASTI!C211 -> 1 | C8: =5*B8 -> 5
A9: X 6 | B9: =ANTIPASTI!C212 -> 0 | C9: =6*B9 -> 0
A10: X 7 | B10: =ANTIPASTI!C213 -> 0 | C10: =7*B10 -> 0
A11: X 8 | B11: =ANTIPASTI!C214 -> 0 | C11: =8*B11 -> 0
A12: X 9 | B12: =ANTIPASTI!C215 -> 1 | C12: =9*B12 -> 9
A13: X 10 | B13: =ANTIPASTI!C216 -> 0 | C13: =10*B13 -> 0
A14: X 11 | B14: =ANTIPASTI!C217 -> 0 | C14: =11*B14 -> 0
A15: X 12 | B15: =ANTIPASTI!C218 -> 0 | C15: =12*B15 -> 0
A16: X 13 | B16: =ANTIPASTI!C219 -> 0 | C16: =13*B16 -> 0
A17: X 14 | B17: =ANTIPASTI!C220 -> 0 | C17: =14*B17 -> 0
A18: X 15 | B18: =ANTIPASTI!C221 -> 0 | C18: =15*B18 -> 0
A19: X 16 | B19: =ANTIPASTI!C222 -> 0 | C19: =16*B19 -> 0
A20: X 17 | B20: =ANTIPASTI!C223 -> 0 | C20: =17*B20 -> 0
A21: X 18 | B21: =ANTIPASTI!C224 -> 0 | C21: =18*B21 -> 0
A22: X 19 | B22: =ANTIPASTI!C225 -> 0 | C22: =19*B22 -> 0
A23: X 20 | B23: =ANTIPASTI!C226 -> 0 | C23: =20*B23 -> 0
A24: X 21 | B24: =ANTIPASTI!C227 -> 0 | C24: =21*B24 -> 0
A25: X 22 | B25: =ANTIPASTI!C228 -> 0 | C25: =22*B25 -> 0
A26: X 23 | B26: =ANTIPASTI!C229 -> 0 | C26: =23*B26 -> 0
A27: X 24 | B27: =ANTIPASTI!C230 -> 0 | C27: =24*B27 -> 0
A28: X 25 | B28: =ANTIPASTI!C231 -> 0 | C28: =25*B28 -> 0
B29: TOTALE | C29: =SUM(C4:C28) -> 66

Sheet POLPO MEDITERRANEA
A1: POLPO ALLA MEDITERRANEA (DIVISIONE IN PORZIONI)
A4: X 1 | B4: =ANTIPASTI!D207 -> 7 | C4: =1*B4 -> 7
A5: X 2 | B5: =ANTIPASTI!D208 -> 13 | C5: =2*B5 -> 26
A6: X 3 | B6: =ANTIPASTI!D209 -> 9 | C6: =3*B6 -> 27
A7: X 4 | B7: =ANTIPASTI!D210 -> 6 | C7: =4*B7 -> 24
A8: X 5 | B8: =ANTIPASTI!D211 -> 2 | C8: =5*B8 -> 10
A9: X 6 | B9: =ANTIPASTI!D212 -> 3 | C9: =6*B9 -> 18
A10: X 7 | B10: =ANTIPASTI!D213 -> 0 | C10: =7*B10 -> 0
A11: X 8 | B11: =ANTIPASTI!D214 -> 1 | C11: =8*B11 -> 8
A12: X 9 | B12: =ANTIPASTI!D215 -> 0 | C12: =9*B12 -> 0
A13: X 10 | B13: =ANTIPASTI!D216 -> 0 | C13: =10*B13 -> 0
A14: X 11 | B14: =ANTIPASTI!D217 -> 0 | C14: =11*B14 -> 0
A15: X 12 | B15: =ANTIPASTI!D218 -> 0 | C15: =12*B15 -> 0
A16: X 13 | B16: =ANTIPASTI!D219 -> 0 | C16: =13*B16 -> 0
A17: X 14 | B17: =ANTIPASTI!D220 -> 0 | C17: =14*B17 -> 0
A18: X 15 | B18: =ANTIPASTI!D221 -> 0 | C18: =15*B18 -> 0
A19: X 16 | B19: =ANTIPASTI!D222 -> 0 | C19: =16*B19 -> 0
A20: X 17 | B20: =ANTIPASTI!D223 -> 0 | C20: =17*B20 -> 0
A21: X 18 | B21: =ANTIPASTI!D224 -> 0 | C21: =18*B21 -> 0
A22: X 19 | B22: =ANTIPASTI!D225 -> 0 | C22: =19*B22 -> 0
A23: X 20 | B23: =ANTIPASTI!D226 -> 0 | C23: =20*B23 -> 0
A24: X 21 | B24: =ANTIPASTI!D227 -> 0 | C24: =21*B24 -> 0
A25: X 22 | B25: =ANTIPASTI!D228 -> 0 | C25: =22*B25 -> 0
A26: X 23 | B26: =ANTIPASTI!D229 -> 0 | C26: =23*B26 -> 0
A27: X 24 | B27: =ANTIPASTI!D230 -> 0 | C27: =24*B27 -> 0
A28: X 25 | B28: =ANTIPASTI!D231 -> 0 | C28: =25*B28 -> 0
B29: TOTALE | C29: =SUM(C4:C28) -> 120

Sheet POLPO E PATATE
A1: POLPO E PATATE (DIVISIONE IN PORZIONI)
A4: X 1 | B4: =ANTIPASTI!E207 -> 8 | C4: =1*B4 -> 8
A5: X 2 | B5: =ANTIPASTI!E208 -> 12 | C5: =2*B5 -> 24
A6: X 3 | B6: =ANTIPASTI!E209 -> 8 | C6: =3*B6 -> 24
A7: X 4 | B7: =ANTIPASTI!E210 -> 5 | C7: =4*B7 -> 20
A8: X 5 | B8: =ANTIPASTI!E211 -> 0 | C8: =5*B8 -> 0
A9: X 6 | B9: =ANTIPASTI!E212 -> 4 | C9: =6*B9 -> 24
A10: X 7 | B10: =ANTIPASTI!E213 -> 1 | C10: =7*B10 -> 7
A11: X 8 | B11: =ANTIPASTI!E214 -> 3 | C11: =8*B11 -> 24
A12: X 9 | B12: =ANTIPASTI!E215 -> 0 | C12: =9*B12 -> 0
A13: X 10 | B13: =ANTIPASTI!E216 -> 2 | C13: =10*B13 -> 20
A14: X 11 | B14: =ANTIPASTI!E217 -> 0 | C14: =11*B14 -> 0
A15: X 12 | B15: =ANTIPASTI!E218 -> 0 | C15: =12*B15 -> 0
A16: X 13 | B16: =ANTIPASTI!E219 -> 0 | C16: =13*B16 -> 0
A17: X 14 | B17: =ANTIPASTI!E220 -> 0 | C17: =14*B17 -> 0
A18: X 15 | B18: =ANTIPASTI!E221 -> 0 | C18: =15*B18 -> 0
A19: X 16 | B19: =ANTIPASTI!E222 -> 0 | C19: =16*B19 -> 0
A20: X 17 | B20: =ANTIPASTI!E223 -> 0 | C20: =17*B20 -> 0
A21: X 18 | B21: =ANTIPASTI!E224 -> 0 | C21: =18*B21 -> 0
A22: X 19 | B22: =ANTIPASTI!E225 -> 0 | C22: =19*B22 -> 0
A23: X 20 | B23: =ANTIPASTI!E226 -> 0 | C23: =20*B23 -> 0
A24: X 21 | B24: =ANTIPASTI!E227 -> 0 | C24: =21*B24 -> 0
A25: X 22 | B25: =ANTIPASTI!E228 -> 0 | C25: =22*B25 -> 0
A26: X 23 | B26: =ANTIPASTI!E229 -> 0 | C26: =23*B26 -> 0
A27: X 24 | B27: =ANTIPASTI!E230 -> 0 | C27: =24*B27 -> 0
A28: X 25 | B28: =ANTIPASTI!E231 -> 0 | C28: =25*B28 -> 0
B29: TOTALE | C29: =SUM(C4:C28) -> 151

Sheet INSALATA DI MARE
A1: INSALATA DI MARE (DIVISIONE IN PORZIONI)
A4: X 1 | B4: =ANTIPASTI!F207 -> 6 | C4: =1*B4 -> 6
A5: X 2 | B5: =ANTIPASTI!F208 -> 10 | C5: =2*B5 -> 20
A6: X 3 | B6: =ANTIPASTI!F209 -> 10 | C6: =3*B6 -> 30
A7: X 4 | B7: =ANTIPASTI!F210 -> 11 | C7: =4*B7 -> 44
A8: X 5 | B8: =ANTIPASTI!F211 -> 3 | C8: =5*B8 -> 15
A9: X 6 | B9: =ANTIPASTI!F212 -> 6 | C9: =6*B9 -> 36
A10: X 7 | B10: =ANTIPASTI!F213 -> 1 | C10: =7*B10 -> 7
A11: X 8 | B11: =ANTIPASTI!F214 -> 4 | C11: =8*B11 -> 32
A12: X 9 | B12: =ANTIPASTI!F215 -> 1 | C12: =9*B12 -> 9
A13: X 10 | B13: =ANTIPASTI!F216 -> 2 | C13: =10*B13 -> 20
A14: X 11 | B14: =ANTIPASTI!F217 -> 0 | C14: =11*B14 -> 0
A15: X 12 | B15: =ANTIPASTI!F218 -> 0 | C15: =12*B15 -> 0
A16: X 13 | B16: =ANTIPASTI!F219 -> 0 | C16: =13*B16 -> 0
A17: X 14 | B17: =ANTIPASTI!F220 -> 0 | C17: =14*B17 -> 0
A18: X 15 | B18: =ANTIPASTI!F221 -> 0 | C18: =15*B18 -> 0
A19: X 16 | B19: =ANTIPASTI!F222 -> 0 | C19: =16*B19 -> 0
A20: X 17 | B20: =ANTIPASTI!F223 -> 0 | C20: =17*B20 -> 0
A21: X 18 | B21: =ANTIPASTI!F224 -> 0 | C21: =18*B21 -> 0
A22: X 19 | B22: =ANTIPASTI!F225 -> 0 | C22: =19*B22 -> 0
A23: X 20 | B23: =ANTIPASTI!F226 -> 0 | C23: =20*B23 -> 0
A24: X 21 | B24: =ANTIPASTI!F227 -> 0 | C24: =21*B24 -> 0
A25: X 22 | B25: =ANTIPASTI!F228 -> 0 | C25: =22*B25 -> 0
A26: X 23 | B26: =ANTIPASTI!F229 -> 0 | C26: =23*B26 -> 0
A27: X 24 | B27: =ANTIPASTI!F230 -> 0 | C27: =24*B27 -> 0
A28: X 25 | B28: =ANTIPASTI!F231 -> 0 | C28: =25*B28 -> 0
B29: TOTALE | C29: =SUM(C4:C28) -> 219

Sheet INSALATA RUSSA
A1: INSALATA RUSSA CON GAMBERI (DIVISIONE IN PORZIONI)
A4: X 1 | B4: =ANTIPASTI!G207 -> 9 | C4: =1*B4 -> 9
A5: X 2 | B5: =ANTIPASTI!G208 -> 12 | C5: =2*B5 -> 24
A6: X 3 | B6: =ANTIPASTI!G209 -> 4 | C6: =3*B6 -> 12
A7: X 4 | B7: =ANTIPASTI!G210 -> 1 | C7: =4*B7 -> 4
A8: X 5 | B8: =ANTIPASTI!G211 -> 1 | C8: =5*B8 -> 5
A9: X 6 | B9: =ANTIPASTI!G212 -> 2 | C9: =6*B9 -> 12
A10: X 7 | B10: =ANTIPASTI!G213 -> 0 | C10: =7*B10 -> 0
A11: X 8 | B11: =ANTIPASTI!G214 -> 0 | C11: =8*B11 -> 0
A12: X 9 | B12: =ANTIPASTI!G215 -> 0 | C12: =9*B12 -> 0
A13: X 10 | B13: =ANTIPASTI!G216 -> 0 | C13: =10*B13 -> 0
A14: X 11 | B14: =ANTIPASTI!G217 -> 0 | C14: =11*B14 -> 0
A15: X 12 | B15: =ANTIPASTI!G218 -> 0 | C15: =12*B15 -> 0
A16: X 13 | B16: =ANTIPASTI!G219 -> 0 | C16: =13*B16 -> 0
A17: X 14 | B17: =ANTIPASTI!G220 -> 0 | C17: =14*B17 -> 0
A18: X 15 | B18: =ANTIPASTI!G221 -> 0 | C18: =15*B18 -> 0
A19: X 16 | B19: =ANTIPASTI!G222 -> 0 | C19: =16*B19 -> 0
B20: TOTALE | C20: =SUM(C4:C19) -> 66

Sheet COCKTAIL GAMBERI
A1: COCKTAIL DI GAMBERI (DIVISIONE IN PORZIONI)
A4: X 1 | B4: =ANTIPASTI!H207 -> 4 | C4: =1*B4 -> 4
A5: X 2 | B5: =ANTIPASTI!H208 -> 20 | C5: =2*B5 -> 40
A6: X 3 | B6: =ANTIPASTI!H209 -> 11 | C6: =3*B6 -> 33
A7: X 4 | B7: =ANTIPASTI!H210 -> 7 | C7: =4*B7 -> 28
A8: X 5 | B8: =ANTIPASTI!H211 -> 3 | C8: =5*B8 -> 15
A9: X 6 | B9: =ANTIPASTI!H212 -> 3 | C9: =6*B9 -> 18
A10: X 7 | B10: =ANTIPASTI!H213 -> 1 | C10: =7*B10 -> 7
A11: X 8 | B11: =ANTIPASTI!H214 -> 2 | C11: =8*B11 -> 16
A12: X 9 | B12: =ANTIPASTI!H215 -> 0 | C12: =9*B12 -> 0
A13: X 10 | B13: =ANTIPASTI!H216 -> 2 | C13: =10*B13 -> 20
A14: X 11 | B14: =ANTIPASTI!H217 -> 0 | C14: =11*B14 -> 0
A15: X 12 | B15: =ANTIPASTI!H218 -> 1 | C15: =12*B15 -> 12
A16: X 13 | B16: =ANTIPASTI!H219 -> 0 | C16: =13*B16 -> 0
A17: X 14 | B17: =ANTIPASTI!H220 -> 0 | C17: =14*B17 -> 0
A18: X 15 | B18: =ANTIPASTI!H221 -> 0 | C18: =15*B18 -> 0
A19: X 16 | B19: =ANTIPASTI!H222 -> 0 | C19: =16*B19 -> 0
A20: X 17 | B20: =ANTIPASTI!H223 -> 0 | C20: =17*B20 -> 0
A21: X 18 | B21: =ANTIPASTI!H224 -> 0 | C21: =18*B21 -> 0
A22: X 19 | B22: =ANTIPASTI!H225 -> 0 | C22: =19*B22 -> 0
A23: X 20 | B23: =ANTIPASTI!H226 -> 0 | C23: =20*B23 -> 0
A24: X 21 | B24: =ANTIPASTI!H227 -> 0 | C24: =21*B24 -> 0
A25: X 22 | B25: =ANTIPASTI!H228 -> 0 | C25: =22*B25 -> 0
A26: X 23 | B26: =ANTIPASTI!H229 -> 0 | C26: =23*B26 -> 0
A27: X 24 | B27: =ANTIPASTI!H230 -> 0 | C27: =24*B27 -> 0
A28: X 25 | B28: =ANTIPASTI!H231 -> 0 | C28: =25*B28 -> 0
B29: TOTALE | C29: =SUM(C4:C28) -> 193

Sheet INSALATA BACCALA
A1: INSALATA BACCALA', CARCIOFINI, SEDANO E CECI (DIVISIONE IN PORZIONI)
A4: X 1 | B4: =ANTIPASTI!I207 -> 8 | C4: =1*B4 -> 8
A5: X 2 | B5: =ANTIPASTI!I208 -> 14 | C5: =2*B5 -> 28
A6: X 3 | B6: =ANTIPASTI!I209 -> 10 | C6: =3*B6 -> 30
A7: X 4 | B7: =ANTIPASTI!I210 -> 3 | C7: =4*B7 -> 12
A8: X 5 | B8: =ANTIPASTI!I211 -> 1 | C8: =5*B8 -> 5
A9: X 6 | B9: =ANTIPASTI!I212 -> 1 | C9: =6*B9 -> 6
A10: X 7 | B10: =ANTIPASTI!I213 -> 0 | C10: =7*B10 -> 0
A11: X 8 | B11: =ANTIPASTI!I214 -> 2 | C11: =8*B11 -> 16
A12: X 9 | B12: =ANTIPASTI!I215 -> 1 | C12: =9*B12 -> 9
A13: X 10 | B13: =ANTIPASTI!I216 -> 0 | C13: =10*B13 -> 0
A14: X 11 | B14: =ANTIPASTI!I217 -> 0 | C14: =11*B14 -> 0
A15: X 12 | B15: =ANTIPASTI!I218 -> 0 | C15: =12*B15 -> 0
A16: X 13 | B16: =ANTIPASTI!I219 -> 0 | C16: =13*B16 -> 0
A17: X 14 | B17: =ANTIPASTI!I220 -> 0 | C17: =14*B17 -> 0
A18: X 15 | B18: =ANTIPASTI!I221 -> 0 | C18: =15*B18 -> 0
A19: X 16 | B19: =ANTIPASTI!I222 -> 0 | C19: =16*B19 -> 0
A20: X 17 | B20: =ANTIPASTI!I223 -> 0 | C20: =17*B20 -> 0
A21: X 18 | B21: =ANTIPASTI!I224 -> 0 | C21: =18*B21 -> 0
B22: TOTALE | C22: =SUM(C4:C21) -> 114

Sheet GAMBERI CATALANA
A1: GAMBERI ALLA CATALANA (DIVISIONE IN PORZIONI)
A4: X 1 | B4: =ANTIPASTI!J207 -> 8 | C4: =1*B4 -> 8
A5: X 2 | B5: =ANTIPASTI!J208 -> 15 | C5: =2*B5 -> 30
A6: X 3 | B6: =ANTIPASTI!J209 -> 7 | C6: =3*B6 -> 21
A7: X 4 | B7: =ANTIPASTI!J210 -> 8 | C7: =4*B7 -> 32
A8: X 5 | B8: =ANTIPASTI!J211 -> 2 | C8: =5*B8 -> 10
A9: X 6 | B9: =ANTIPASTI!J212 -> 0 | C9: =6*B9 -> 0
A10: X 7 | B10: =ANTIPASTI!J213 -> 0 | C10: =7*B10 -> 0
A11: X 8 | B11: =ANTIPASTI!J214 -> 2 | C11: =8*B11 -> 16
A12: X 9 | B12: =ANTIPASTI!J215 -> 0 | C12: =9*B12 -> 0
A13: X 10 | B13: =ANTIPASTI!J216 -> 3 | C13: =10*B13 -> 30
A14: X 11 | B14: =ANTIPASTI!J217 -> 0 | C14: =11*B14 -> 0
A15: X 12 | B15: =ANTIPASTI!J218 -> 0 | C15: =12*B15 -> 0
A16: X 13 | B16: =ANTIPASTI!J219 -> 0 | C16: =13*B16 -> 0
A17: X 14 | B17: =ANTIPASTI!J220 -> 0 | C17: =14*B17 -> 0
A18: X 15 | B18: =ANTIPASTI!J221 -> 0 | C18: =15*B18 -> 0
A19: X 16 | B19: =ANTIPASTI!J222 -> 0 | C19: =16*B19 -> 0
A20: X 17 | B20: =ANTIPASTI!J223 -> 0 | C20: =17*B20 -> 0
B21: TOTALE | C21: =SUM(C4:C20) -> 147

Sheet FLAN
A1: FLAN CAPESANTE CON ZUCCHINE (DIVISIONE IN PORZIONI)
A4: X 1 | B4: =ANTIPASTI!K207 -> 3 | C4: =1*B4 -> 3
A5: X 2 | B5: =ANTIPASTI!K208 -> 6 | C5: =2*B5 -> 12
A6: X 3 | B6: =ANTIPASTI!K209 -> 3 | C6: =3*B6 -> 9
A7: X 4 | B7: =ANTIPASTI!K210 -> 8 | C7: =4*B7 -> 32
A8: X 5 | B8: =ANTIPASTI!K211 -> 2 | C8: =5*B8 -> 10
A9: X 6 | B9: =ANTIPASTI!K212 -> 3 | C9: =6*B9 -> 18
A10: X 7 | B10: =ANTIPASTI!K213 -> 0 | C10: =7*B10 -> 0
A11: X 8 | B11: =ANTIPASTI!K214 -> 3 | C11: =8*B11 -> 24
A12: X 9 | B12: =ANTIPASTI!K215 -> 0 | C12: =9*B12 -> 0
A13: X 10 | B13: =ANTIPASTI!K216 -> 0 | C13: =10*B13 -> 0
A14: X 11 | B14: =ANTIPASTI!K217 -> 0 | C14: =11*B14 -> 0
A15: X 12 | B15: =ANTIPASTI!K218 -> 0 | C15: =12*B15 -> 0
A16: X 13 | B16: =ANTIPASTI!K219 -> 0 | C16: =13*B16 -> 0
A17: X 14 | B17: =ANTIPASTI!K220 -> 0 | C17: =14*B17 -> 0
A18: X 15 | B18: =ANTIPASTI!K221 -> 0 | C18: =15*B18 -> 0
B19: TOTALE | C19: =SUM(C4:C18) -> 108

Sheet BRIOCHE SALMONE
A1: BRIOCHE CON SALMONE (DIVISIONE IN PEZZI)
A4: X 1 | B4: =ANTIPASTI!L207 -> 1 | C4: =1*B4 -> 1
A5: X 2 | B5: =ANTIPASTI!L208 -> 6 | C5: =2*B5 -> 12
A6: X 3 | B6: =ANTIPASTI!L209 -> 3 | C6: =3*B6 -> 9
A7: X 4 | B7: =ANTIPASTI!L210 -> 4 | C7: =4*B7 -> 16
A8: X 5 | B8: =ANTIPASTI!L211 -> 3 | C8: =5*B8 -> 15
A9: X 6 | B9: =ANTIPASTI!L212 -> 6 | C9: =6*B9 -> 36
A10: X 7 | B10: =ANTIPASTI!L213 -> 0 | C10: =7*B10 -> 0
A11: X 8 | B11: =ANTIPASTI!L214 -> 1 | C11: =8*B11 -> 8
A12: X 9 | B12: =ANTIPASTI!L215 -> 0 | C12: =9*B12 -> 0
A13: X 10 | B13: =ANTIPASTI!L216 -> 2 | C13: =10*B13 -> 20
A14: X 11 | B14: =ANTIPASTI!L217 -> 0 | C14: =11*B14 -> 0
A15: X 12 | B15: =ANTIPASTI!L218 -> 0 | C15: =12*B15 -> 0
A16: X 13 | B16: =ANTIPASTI!L219 -> 0 | C16: =13*B16 -> 0
A17: X 14 | B17: =ANTIPASTI!L220 -> 0 | C17: =14*B17 -> 0
A18: X 15 | B18: =ANTIPASTI!L221 -> 0 | C18: =15*B18 -> 0
A19: X 16 | B19: =ANTIPASTI!L222 -> 0 | C19: =16*B19 -> 0
A20: X 17 | B20: =ANTIPASTI!L223 -> 0 | C20: =17*B20 -> 0
A21: X 18 | B21: =ANTIPASTI!L224 -> 0 | C21: =18*B21 -> 0
A22: X 19 | B22: =ANTIPASTI!L225 -> 0 | C22: =19*B22 -> 0
A23: X 20 | B23: =ANTIPASTI!L226 -> 0 | C23: =20*B23 -> 0
A24: X 21 | B24: =ANTIPASTI!L227 -> 0 | C24: =21*B24 -> 0
A25: X 22 | B25: =ANTIPASTI!L228 -> 0 | C25: =22*B25 -> 0
A26: X 23 | B26: =ANTIPASTI!L229 -> 0 | C26: =23*B26 -> 0
A27: X 24 | B27: =ANTIPASTI!L230 -> 0 | C27: =24*B27 -> 0
A28: X 25 | B28: =ANTIPASTI!L231 -> 0 | C28: =25*B28 -> 0
B29: TOTALE | C29: =SUM(C4:C28) -> 117

Sheet SFORMATINO
A1: SFORMATINO DI POLENTA CON MOSCARDINI IN UMIDO (DIVISIONE IN PEZZI)
A4: X 1 | B4: =ANTIPASTI!M207 -> 3 | C4: =1*B4 -> 3
A5: X 2 | B5: =ANTIPASTI!M208 -> 9 | C5: =2*B5 -> 18
A6: X 3 | B6: =ANTIPASTI!M209 -> 3 | C6: =3*B6 -> 9
A7: X 4 | B7: =ANTIPASTI!M210 -> 4 | C7: =4*B7 -> 16
A8: X 5 | B8: =ANTIPASTI!M211 -> 4 | C8: =5*B8 -> 20
A9: X 6 | B9: =ANTIPASTI!M212 -> 2 | C9: =6*B9 -> 12
A10: X 7 | B10: =ANTIPASTI!M213 -> 0 | C10: =7*B10 -> 0
A11: X 8 | B11: =ANTIPASTI!M214 -> 4 | C11: =8*B11 -> 32
A12: X 9 | B12: =ANTIPASTI!M215 -> 2 | C12: =9*B12 -> 18
A13: X 10 | B13: =ANTIPASTI!M216 -> 1 | C13: =10*B13 -> 10
A14: X 11 | B14: =ANTIPASTI!M217 -> 0 | C14: =11*B14 -> 0
A15: X 12 | B15: =ANTIPASTI!M218 -> 0 | C15: =12*B15 -> 0
A16: X 13 | B16: =ANTIPASTI!M219 -> 0 | C16: =13*B16 -> 0
A17: X 14 | B17: =ANTIPASTI!M220 -> 0 | C17: =14*B17 -> 0
A18: X 15 | B18: =ANTIPASTI!M221 -> 0 | C18: =15*B18 -> 0
A19: X 16 | B19: =ANTIPASTI!M222 -> 0 | C19: =16*B19 -> 0
A20: X 17 | B20: =ANTIPASTI!M223 -> 0 | C20: =17*B20 -> 0
A21: X 18 | B21: =ANTIPASTI!M224 -> 0 | C21: =18*B21 -> 0
A22: X 19 | B22: =ANTIPASTI!M225 -> 0 | C22: =19*B22 -> 0
A23: X 20 | B23: =ANTIPASTI!M226 -> 0 | C23: =20*B23 -> 0
A24: X 21 | B24: =ANTIPASTI!M227 -> 0 | C24: =21*B24 -> 0
A25: X 22 | B25: =ANTIPASTI!M228 -> 0 | C25: =22*B25 -> 0
A26: X 23 | B26: =ANTIPASTI!M229 -> 0 | C26: =23*B26 -> 0
A27: X 24 | B27: =ANTIPASTI!M230 -> 0 | C27: =24*B27 -> 0
A28: X 25 | B28: =ANTIPASTI!M231 -> 0 | C28: =25*B28 -> 0
B29: TOTALE | C29: =SUM(C4:C28) -> 138

Sheet GAMBERI KATAIFI
A1: GAMBERI IN PASTA KATAIFI (DIVISIONE IN PEZZI)
A4: X 1 | B4: =ANTIPASTI!N207 -> 0 | C4: =1*B4 -> 0
A5: X 2 | B5: =ANTIPASTI!N208 -> 5 | C5: =2*B5 -> 10
A6: X 3 | B6: =ANTIPASTI!N209 -> 3 | C6: =3*B6 -> 9
A7: X 4 | B7: =ANTIPASTI!N210 -> 4 | C7: =4*B7 -> 16
A8: X 5 | B8: =ANTIPASTI!N211 -> 1 | C8: =5*B8 -> 5
A9: X 6 | B9: =ANTIPASTI!N212 -> 2 | C9: =6*B9 -> 12
A10: X 7 | B10: =ANTIPASTI!N213 -> 0 | C10: =7*B10 -> 0
A11: X 8 | B11: =ANTIPASTI!N214 -> 3 | C11: =8*B11 -> 24
A12: X 9 | B12: =ANTIPASTI!N215 -> 0 | C12: =9*B12 -> 0
A13: X 10 | B13: =ANTIPASTI!N216 -> 2 | C13: =10*B13 -> 20
A14: X 11 | B14: =ANTIPASTI!N217 -> 0 | C14: =11*B14 -> 0
A15: X 12 | B15: =ANTIPASTI!N218 -> 0 | C15: =12*B15 -> 0
A16: X 13 | B16: =ANTIPASTI!N219 -> 1 | C16: =13*B16 -> 13
A17: X 14 | B17: =ANTIPASTI!N220 -> 0 | C17: =14*B17 -> 0
A18: X 15 | B18: =ANTIPASTI!N221 -> 0 | C18: =15*B18 -> 0
A19: X 16 | B19: =ANTIPASTI!N222 -> 1 | C19: =16*B19 -> 16
A20: X 17 | B20: =ANTIPASTI!N223 -> 0 | C20: =17*B20 -> 0
A21: X 18 | B21: =ANTIPASTI!N224 -> 1 | C21: =18*B21 -> 18
A22: X 19 | B22: =ANTIPASTI!N225 -> 0 | C22: =19*B22 -> 0
A23: X 20 | B23: =ANTIPASTI!N226 -> 0 | C23: =20*B23 -> 0
A24: X 21 | B24: =ANTIPASTI!N227 -> 0 | C24: =21*B24 -> 0
A25: X 22 | B25: =ANTIPASTI!N228 -> 0 | C25: =22*B25 -> 0
A26: X 23 | B26: =ANTIPASTI!N229 -> 0 | C26: =23*B26 -> 0
A27: X 24 | B27: =ANTIPASTI!N230 -> 0 | C27: =24*B27 -> 0
A28: X 25 | B28: =ANTIPASTI!N231 -> 0 | C28: =25*B28 -> 0
B29: TOTALE | C29: =SUM(C4:C28) -> 143

Sheet PANETTONE
A1: PANETTONE GASTRONOMICO (DIVISIONE IN PEZZI)
A4: X 1 | B4: =ANTIPASTI!O207 -> 12 | C4: =1*B4 -> 12
A5: X 2 | B5: =ANTIPASTI!O208 -> 2 | C5: =2*B5 -> 4
A6: X 3 | B6: =ANTIPASTI!O209 -> 1 | C6: =3*B6 -> 3
A7: X 4 | B7: =ANTIPASTI!O210 -> 0 | C7: =4*B7 -> 0
A8: X 5 | B8: =ANTIPASTI!O211 -> 0 | C8: =5*B8 -> 0
A9: X 6 | B9: =ANTIPASTI!O212 -> 0 | C9: =6*B9 -> 0
A10: X 7 | B10: =ANTIPASTI!O213 -> 0 | C10: =7*B10 -> 0
A11: X 8 | B11: =ANTIPASTI!O214 -> 0 | C11: =8*B11 -> 0
A12: X 9 | B12: =ANTIPASTI!O215 -> 0 | C12: =9*B12 -> 0
A13: X 10 | B13: =ANTIPASTI!O216 -> 0 | C13: =10*B13 -> 0
A14: X 11 | B14: =ANTIPASTI!O217 -> 0 | C14: =11*B14 -> 0
A15: X 12 | B15: =ANTIPASTI!O218 -> 0 | C15: =12*B15 -> 0
A16: X 13 | B16: =ANTIPASTI!O219 -> 0 | C16: =13*B16 -> 0
A17: X 14 | B17: =ANTIPASTI!O220 -> 0 | C17: =14*B17 -> 0
A18: X 15 | B18: =ANTIPASTI!O221 -> 0 | C18: =15*B18 -> 0
A19: X 16 | B19: =ANTIPASTI!O222 -> 0 | C19: =16*B19 -> 0
A20: X 17 | B20: =ANTIPASTI!O223 -> 0 | C20: =17*B20 -> 0
A21: X 18 | B21: =ANTIPASTI!O224 -> 0 | C21: =18*B21 -> 0
A22: X 19 | B22: =ANTIPASTI!O225 -> 0 | C22: =19*B22 -> 0
A23: X 20 | B23: =ANTIPASTI!O226 -> 0 | C23: =20*B23 -> 0
A24: X 21 | B24: =ANTIPASTI!O227 -> 0 | C24: =21*B24 -> 0
A25: X 22 | B25: =ANTIPASTI!O228 -> 0 | C25: =22*B25 -> 0
A26: X 23 | B26: =ANTIPASTI!O229 -> 0 | C26: =23*B26 -> 0
A27: X 24 | B27: =ANTIPASTI!O230 -> 0 | C27: =24*B27 -> 0
A28: X 25 | B28: =ANTIPASTI!O231 -> 0 | C28: =25*B28 -> 0
B29: TOTALE | C29: =SUM(C4:C28) -> 19

Sheet ARAGOSTA BELLAVISTA
A1: ARAGOSTA IN BELLAVISTA - MEZZA (DIVISIONE IN PEZZI)
A4: X 1 | B4: =ANTIPASTI!P207 -> 0 | C4: =1*B4 -> 0
A5: X 2 | B5: =ANTIPASTI!P208 -> 0 | C5: =2*B5 -> 0
A6: X 3 | B6: =ANTIPASTI!P209 -> 0 | C6: =3*B6 -> 0
A7: X 4 | B7: =ANTIPASTI!P210 -> 0 | C7: =4*B7 -> 0
A8: X 5 | B8: =ANTIPASTI!P211 -> 0 | C8: =5*B8 -> 0
A9: X 6 | B9: =ANTIPASTI!P212 -> 0 | C9: =6*B9 -> 0
A10: X 7 | B10: =ANTIPASTI!P213 -> 1 | C10: =7*B10 -> 7
A11: X 8 | B11: =ANTIPASTI!P214 -> 0 | C11: =8*B11 -> 0
A12: X 9 | B12: =ANTIPASTI!P215 -> 0 | C12: =9*B12 -> 0
A13: X 10 | B13: =ANTIPASTI!P216 -> 0 | C13: =10*B13 -> 0
A14: X 11 | B14: =ANTIPASTI!P217 -> 0 | C14: =11*B14 -> 0
A15: X 12 | B15: =ANTIPASTI!P218 -> 0 | C15: =12*B15 -> 0
A16: X 13 | B16: =ANTIPASTI!P219 -> 0 | C16: =13*B16 -> 0
A17: X 14 | B17: =ANTIPASTI!P220 -> 0 | C17: =14*B17 -> 0
A18: X 15 | B18: =ANTIPASTI!P221 -> 0 | C18: =15*B18 -> 0
A19: X 16 | B19: =ANTIPASTI!P222 -> 0 | C19: =16*B19 -> 0
A20: X 17 | B20: =ANTIPASTI!P223 -> 0 | C20: =17*B20 -> 0
A21: X 18 | B21: =ANTIPASTI!P224 -> 0 | C21: =18*B21 -> 0
A22: X 19 | B22: =ANTIPASTI!P225 -> 0 | C22: =19*B22 -> 0
A23: X 20 | B23: =ANTIPASTI!P226 -> 0 | C23: =20*B23 -> 0
A24: X 21 | B24: =ANTIPASTI!P227 -> 0 | C24: =21*B24 -> 0
A25: X 22 | B25: =ANTIPASTI!P228 -> 0 | C25: =22*B25 -> 0
A26: X 23 | B26: =ANTIPASTI!P229 -> 0 | C26: =23*B26 -> 0
A27: X 24 | B27: =ANTIPASTI!P230 -> 0 | C27: =24*B27 -> 0
A28: X 25 | B28: =ANTIPASTI!P231 -> 0 | C28: =25*B28 -> 0
B29: TOTALE | C29: =SUM(C4:C28) -> 7

Sheet PIATTO MISTO
A1: PIATTO MISTO TARTARE (DIVISIONE IN PIATTI)
A4: X 1 | B4: =CRUDI!C204 -> 7 | C4: =1*B4 -> 7
A5: X 2 | B5: =CRUDI!C205 -> 3 | C5: =2*B5 -> 6
A6: X 3 | B6: =CRUDI!C206 -> 0 | C6: =3*B6 -> 0
A7: X 4 | B7: =CRUDI!C207 -> 1 | C7: =4*B7 -> 4
A8: X 5 | B8: =CRUDI!C208 -> 0 | C8: =5*B8 -> 0
A9: X 6 | B9: =CRUDI!C209 -> 0 | C9: =6*B9 -> 0
A10: X 7 | B10: =CRUDI!C210 -> 0 | C10: =7*B10 -> 0
A11: X 8 | B11: =CRUDI!C211 -> 0 | C11: =8*B11 -> 0
A12: X 9 | B12: =CRUDI!C212 -> 0 | C12: =9*B12 -> 0
A13: X 10 | B13: =CRUDI!C213 -> 0 | C13: =10*B13 -> 0
A14: X 11 | B14: =CRUDI!C214 -> 0 | C14: =11*B14 -> 0
A15: X 12 | B15: =CRUDI!C215 -> 0 | C15: =12*B15 -> 0
A16: X 13 | B16: =CRUDI!C216 -> 0 | C16: =13*B16 -> 0
A17: X 14 | B17: =CRUDI!C217 -> 0 | C17: =14*B17 -> 0
A18: X 15 | B18: =CRUDI!C218 -> 0 | C18: =15*B18 -> 0
A19: X 16 | B19: =CRUDI!C219 -> 0 | C19: =16*B19 -> 0
A20: X 17 | B20: =CRUDI!C220 -> 0 | C20: =17*B20 -> 0
A21: X 18 | B21: =CRUDI!C221 -> 0 | C21: =18*B21 -> 0
A22: X 19 | B22: =CRUDI!C222 -> 0 | C22: =19*B22 -> 0
A23: X 20 | B23: =CRUDI!C223 -> 0 | C23: =20*B23 -> 0
A24: X 21 | B24: =CRUDI!C224 -> 0 | C24: =21*B24 -> 0
A25: X 22 | B25: =CRUDI!C225 -> 0 | C25: =22*B25 -> 0
A26: X 23 | B26: =CRUDI!C226 -> 0 | C26: =23*B26 -> 0
A27: X 24 | B27: =CRUDI!C227 -> 0 | C27: =24*B27 -> 0
A28: X 25 | B28: =CRUDI!C228 -> 0 | C28: =25*B28 -> 0
B29: TOTALE | C29: =SUM(C4:C28) -> 17

Sheet MAREMIO
A1: MAREMIO CARPACCI X 1 (DIVISIONE IN PIATTI)
A4: X 1 | B4: =CRUDI!D204 -> 10 | C4: =1*B4 -> 10
A5: X 2 | B5: =CRUDI!D205 -> 6 | C5: =2*B5 -> 12
A6: X 3 | B6: =CRUDI!D206 -> 3 | C6: =3*B6 -> 9
A7: X 4 | B7: =CRUDI!D207 -> 1 | C7: =4*B7 -> 4
A8: X 5 | B8: =CRUDI!D208 -> 0 | C8: =5*B8 -> 0
A9: X 6 | B9: =CRUDI!D209 -> 0 | C9: =6*B9 -> 0
A10: X 7 | B10: =CRUDI!D210 -> 0 | C10: =7*B10 -> 0
A11: X 8 | B11: =CRUDI!D211 -> 0 | C11: =8*B11 -> 0
A12: X 9 | B12: =CRUDI!D212 -> 1 | C12: =9*B12 -> 9
A13: X 10 | B13: =CRUDI!D213 -> 0 | C13: =10*B13 -> 0
A14: X 11 | B14: =CRUDI!D214 -> 0 | C14: =11*B14 -> 0
A15: X 12 | B15: =CRUDI!D215 -> 0 | C15: =12*B15 -> 0
A16: X 13 | B16: =CRUDI!D216 -> 0 | C16: =13*B16 -> 0
A17: X 14 | B17: =CRUDI!D217 -> 0 | C17: =14*B17 -> 0
A18: X 15 | B18: =CRUDI!D218 -> 0 | C18: =15*B18 -> 0
B19: TOTALE | C19: =SUM(C4:C18) -> 44

Sheet TART TONNO
A1: TARTARE TONNO 120 GR (DIVISIONE IN PEZZI)
A4: X 1 | B4: =CRUDI!E204 -> 1 | C4: =1*B4 -> 1
A5: X 2 | B5: =CRUDI!E205 -> 6 | C5: =2*B5 -> 12
A6: X 3 | B6: =CRUDI!E206 -> 2 | C6: =3*B6 -> 6
A7: X 4 | B7: =CRUDI!E207 -> 2 | C7: =4*B7 -> 8
A8: X 5 | B8: =CRUDI!E208 -> 0 | C8: =5*B8 -> 0
A9: X 6 | B9: =CRUDI!E209 -> 0 | C9: =6*B9 -> 0
A10: X 7 | B10: =CRUDI!E210 -> 0 | C10: =7*B10 -> 0
A11: X 8 | B11: =CRUDI!E211 -> 0 | C11: =8*B11 -> 0
A12: X 9 | B12: =CRUDI!E212 -> 0 | C12: =9*B12 -> 0
A13: X 10 | B13: =CRUDI!E213 -> 0 | C13: =10*B13 -> 0
A14: X 11 | B14: =CRUDI!E214 -> 0 | C14: =11*B14 -> 0
A15: X 12 | B15: =CRUDI!E215 -> 0 | C15: =12*B15 -> 0
A16: X 13 | B16: =CRUDI!E216 -> 0 | C16: =13*B16 -> 0
A17: X 14 | B17: =CRUDI!E217 -> 0 | C17: =14*B17 -> 0
A18: X 15 | B18: =CRUDI!E218 -> 0 | C18: =15*B18 -> 0
B19: TOTALE | C19: =SUM(C4:C18) -> 27

Sheet TART SALMONE
A1: TARTARE SALMONE 120 GR (DIVISIONE IN PEZZI)
A4: X 1 | B4: =CRUDI!F204 -> 5 | C4: =1*B4 -> 5
A5: X 2 | B5: =CRUDI!F205 -> 4 | C5: =2*B5 -> 8
A6: X 3 | B6: =CRUDI!F206 -> 0 | C6: =3*B6 -> 0
A7: X 4 | B7: =CRUDI!F207 -> 0 | C7: =4*B7 -> 0
A8: X 5 | B8: =CRUDI!F208 -> 0 | C8: =5*B8 -> 0
A9: X 6 | B9: =CRUDI!F209 -> 0 | C9: =6*B9 -> 0
A10: X 7 | B10: =CRUDI!F210 -> 0 | C10: =7*B10 -> 0
A11: X 8 | B11: =CRUDI!F211 -> 0 | C11: =8*B11 -> 0
A12: X 9 | B12: =CRUDI!F212 -> 0 | C12: =9*B12 -> 0
A13: X 10 | B13: =CRUDI!F213 -> 0 | C13: =10*B13 -> 0
A14: X 11 | B14: =CRUDI!F214 -> 0 | C14: =11*B14 -> 0
A15: X 12 | B15: =CRUDI!F215 -> 0 | C15: =12*B15 -> 0
A16: X 13 | B16: =CRUDI!F216 -> 0 | C16: =13*B16 -> 0
A17: X 14 | B17: =CRUDI!F217 -> 0 | C17: =14*B17 -> 0
A18: X 15 | B18: =CRUDI!F218 -> 0 | C18: =15*B18 -> 0
B19: TOTALE | C19: =SUM(C4:C18) -> 13

Sheet TART ORATA
A1: TARTARE ORATA 120 GR (DIVISIONE IN PEZZI)
A4: X 1 | B4: =CRUDI!G204 -> 2 | C4: =1*B4 -> 2
A5: X 2 | B5: =CRUDI!G205 -> 0 | C5: =2*B5 -> 0
A6: X 3 | B6: =CRUDI!G206 -> 0 | C6: =3*B6 -> 0
A7: X 4 | B7: =CRUDI!G207 -> 0 | C7: =4*B7 -> 0
A8: X 5 | B8: =CRUDI!G208 -> 0 | C8: =5*B8 -> 0
A9: X 6 | B9: =CRUDI!G209 -> 0 | C9: =6*B9 -> 0
A10: X 7 | B10: =CRUDI!G210 -> 0 | C10: =7*B10 -> 0
A11: X 8 | B11: =CRUDI!G211 -> 0 | C11: =8*B11 -> 0
A12: X 9 | B12: =CRUDI!G212 -> 0 | C12: =9*B12 -> 0
A13: X 10 | B13: =CRUDI!G213 -> 0 | C13: =10*B13 -> 0
A14: X 11 | B14: =CRUDI!G214 -> 0 | C14: =11*B14 -> 0
A15: X 12 | B15: =CRUDI!G215 -> 0 | C15: =12*B15 -> 0
A16: X 13 | B16: =CRUDI!G216 -> 0 | C16: =13*B16 -> 0
A17: X 14 | B17: =CRUDI!G217 -> 0 | C17: =14*B17 -> 0
A18: X 15 | B18: =CRUDI!G218 -> 0 | C18: =15*B18 -> 0
B19: TOTALE | C19: =SUM(C4:C18) -> 2

Sheet TART BRANZINO
A1: TARTARE BRANZINO 120 GR (DIVISIONE IN PEZZI)
A4: X 1 | B4: =CRUDI!H204 -> 1 | C4: =1*B4 -> 1
A5: X 2 | B5: =CRUDI!H205 -> 3 | C5: =2*B5 -> 6
A6: X 3 | B6: =CRUDI!H206 -> 0 | C6: =3*B6 -> 0
A7: X 4 | B7: =CRUDI!H207 -> 0 | C7: =4*B7 -> 0
A8: X 5 | B8: =CRUDI!H208 -> 0 | C8: =5*B8 -> 0
A9: X 6 | B9: =CRUDI!H209 -> 0 | C9: =6*B9 -> 0
A10: X 7 | B10: =CRUDI!H210 -> 0 | C10: =7*B10 -> 0
A11: X 8 | B11: =CRUDI!H211 -> 0 | C11: =8*B11 -> 0
A12: X 9 | B12: =CRUDI!H212 -> 0 | C12: =9*B12 -> 0
A13: X 10 | B13: =CRUDI!H213 -> 0 | C13: =10*B13 -> 0
A14: X 11 | B14: =CRUDI!H214 -> 0 | C14: =11*B14 -> 0
A15: X 12 | B15: =CRUDI!H215 -> 0 | C15: =12*B15 -> 0
A16: X 13 | B16: =CRUDI!H216 -> 0 | C16: =13*B16 -> 0
A17: X 14 | B17: =CRUDI!H217 -> 0 | C17: =14*B17 -> 0
A18: X 15 | B18: =CRUDI!H218 -> 0 | C18: =15*B18 -> 0
B19: TOTALE | C19: =SUM(C4:C18) -> 7

Sheet LASAGNA MAZZANCOLLE
A1: LASAGNA MAZZANCOLLE, RADICCHIO E SCAMORZA (DIVISIONE IN VASCHETTE)
A4: X 1 | B4: =PRIMI!C204 -> 15 | C4: =1*B4 -> 15
A5: X 2 | B5: =PRIMI!C205 -> 11 | C5: =2*B5 -> 22
A6: X 3 | B6: =PRIMI!C206 -> 3 | C6: =3*B6 -> 9
A7: X 4 | B7: =PRIMI!C207 -> 4 | C7: =4*B7 -> 16
A8: X 5 | B8: =PRIMI!C208 -> 1 | C8: =5*B8 -> 5
A9: X 6 | B9: =PRIMI!C209 -> 0 | C9: =6*B9 -> 0
A10: X 7 | B10: =PRIMI!C210 -> 0 | C10: =7*B10 -> 0
A11: X 8 | B11: =PRIMI!C211 -> 0 | C11: =8*B11 -> 0
A12: X 9 | B12: =PRIMI!C212 -> 0 | C12: =9*B12 -> 0
A13: X 10 | B13: =PRIMI!C213 -> 0 | C13: =10*B13 -> 0
A14: X 11 | B14: =PRIMI!C214 -> 0 | C14: =11*B14 -> 0
A15: X 12 | B15: =PRIMI!C215 -> 0 | C15: =12*B15 -> 0
A16: X 13 | B16: =PRIMI!C216 -> 0 | C16: =13*B16 -> 0
A17: X 14 | B17: =PRIMI!C217 -> 0 | C17: =14*B17 -> 0
A18: X 15 | B18: =PRIMI!C218 -> 0 | C18: =15*B18 -> 0
B19: TOTALE | C19: =SUM(C4:C18) -> 67

Sheet CRESPELLE GAMBERI
A1: CRESPELLE GAMBERI E ZUCCHINE (DIVISIONE IN VASCHETTE)
A4: X 1 | B4: =PRIMI!D204 -> 10 | C4: =1*B4 -> 10
A5: X 2 | B5: =PRIMI!D205 -> 4 | C5: =2*B5 -> 8
A6: X 3 | B6: =PRIMI!D206 -> 3 | C6: =3*B6 -> 9
A7: X 4 | B7: =PRIMI!D207 -> 2 | C7: =4*B7 -> 8
A8: X 5 | B8: =PRIMI!D208 -> 0 | C8: =5*B8 -> 0
A9: X 6 | B9: =PRIMI!D209 -> 2 | C9: =6*B9 -> 12
A10: X 7 | B10: =PRIMI!D210 -> 0 | C10: =7*B10 -> 0
A11: X 8 | B11: =PRIMI!D211 -> 1 | C11: =8*B11 -> 8
A12: X 9 | B12: =PRIMI!D212 -> 0 | C12: =9*B12 -> 0
A13: X 10 | B13: =PRIMI!D213 -> 0 | C13: =10*B13 -> 0
A14: X 11 | B14: =PRIMI!D214 -> 0 | C14: =11*B14 -> 0
A15: X 12 | B15: =PRIMI!D215 -> 0 | C15: =12*B15 -> 0
A16: X 13 | B16: =PRIMI!D216 -> 0 | C16: =13*B16 -> 0
A17: X 14 | B17: =PRIMI!D217 -> 0 | C17: =14*B17 -> 0
A18: X 15 | B18: =PRIMI!D218 -> 0 | C18: =15*B18 -> 0
B19: TOTALE | C19: =SUM(C4:C18) -> 55

Sheet LASAGNA BRANZINO
A1: LASAGNA BRANZINO E CARCIOFI (DIVISIONE IN VASCHETTE)
A4: X 1 | B4: =PRIMI!E204 -> 12 | C4: =1*B4 -> 12
A5: X 2 | B5: =PRIMI!E205 -> 4 | C5: =2*B5 -> 8
A6: X 3 | B6: =PRIMI!E206 -> 1 | C6: =3*B6 -> 3
A7: X 4 | B7: =PRIMI!E207 -> 0 | C7: =4*B7 -> 0
A8: X 5 | B8: =PRIMI!E208 -> 0 | C8: =5*B8 -> 0
A9: X 6 | B9: =PRIMI!E209 -> 0 | C9: =6*B9 -> 0
A10: X 7 | B10: =PRIMI!E210 -> 0 | C10: =7*B10 -> 0
A11: X 8 | B11: =PRIMI!E211 -> 0 | C11: =8*B11 -> 0
A12: X 9 | B12: =PRIMI!E212 -> 0 | C12: =9*B12 -> 0
A13: X 10 | B13: =PRIMI!E213 -> 0 | C13: =10*B13 -> 0
A14: X 11 | B14: =PRIMI!E214 -> 0 | C14: =11*B14 -> 0
A15: X 12 | B15: =PRIMI!E215 -> 0 | C15: =12*B15 -> 0
A16: X 13 | B16: =PRIMI!E216 -> 0 | C16: =13*B16 -> 0
A17: X 14 | B17: =PRIMI!E217 -> 0 | C17: =14*B17 -> 0
A18: X 15 | B18: =PRIMI!E218 -> 0 | C18: =15*B18 -> 0
B19: TOTALE | C19: =SUM(C4:C18) -> 23

Sheet CANNELLONI
A1: CANNELLONI SALMONE E RICOTTA (DIVISIONE IN VASCHETTE)
A4: X 1 | B4: =PRIMI!F204 -> 7 | C4: =1*B4 -> 7
A5: X 2 | B5: =PRIMI!F205 -> 3 | C5: =2*B5 -> 6
A6: X 3 | B6: =PRIMI!F206 -> 1 | C6: =3*B6 -> 3
A7: X 4 | B7: =PRIMI!F207 -> 1 | C7: =4*B7 -> 4
A8: X 5 | B8: =PRIMI!F208 -> 0 | C8: =5*B8 -> 0
A9: X 6 | B9: =PRIMI!F209 -> 0 | C9: =6*B9 -> 0
A10: X 7 | B10: =PRIMI!F210 -> 0 | C10: =7*B10 -> 0
A11: X 8 | B11: =PRIMI!F211 -> 0 | C11: =8*B11 -> 0
A12: X 9 | B12: =PRIMI!F212 -> 0 | C12: =9*B12 -> 0
A13: X 10 | B13: =PRIMI!F213 -> 0 | C13: =10*B13 -> 0
A14: X 11 | B14: =PRIMI!F214 -> 0 | C14: =11*B14 -> 0
A15: X 12 | B15: =PRIMI!F215 -> 0 | C15: =12*B15 -> 0
A16: X 13 | B16: =PRIMI!F216 -> 0 | C16: =13*B16 -> 0
A17: X 14 | B17: =PRIMI!F217 -> 0 | C17: =14*B17 -> 0
A18: X 15 | B18: =PRIMI!F218 -> 0 | C18: =15*B18 -> 0
B19: TOTALE | C19: =SUM(C4:C18) -> 20

Sheet CAPESANTE
A1: CAPESANTE GRATINATE (DIVISIONE IN PEZZI)
A4: X 1 | B4: =PRIMI!G204 -> 0 | C4: =1*B4 -> 0
A5: X 2 | B5: =PRIMI!G205 -> 2 | C5: =2*B5 -> 4
A6: X 3 | B6: =PRIMI!G206 -> 1 | C6: =3*B6 -> 3
A7: X 4 | B7: =PRIMI!G207 -> 5 | C7: =4*B7 -> 20
A8: X 5 | B8: =PRIMI!G208 -> 2 | C8: =5*B8 -> 10
A9: X 6 | B9: =PRIMI!G209 -> 4 | C9: =6*B9 -> 24
A10: X 7 | B10: =PRIMI!G210 -> 2 | C10: =7*B10 -> 14
A11: X 8 | B11: =PRIMI!G211 -> 4 | C11: =8*B11 -> 32
A12: X 9 | B12: =PRIMI!G212 -> 0 | C12: =9*B12 -> 0
A13: X 10 | B13: =PRIMI!G213 -> 4 | C13: =10*B13 -> 40
A14: X 11 | B14: =PRIMI!G214 -> 0 | C14: =11*B14 -> 0
A15: X 12 | B15: =PRIMI!G215 -> 4 | C15: =12*B15 -> 48
A16: X 13 | B16: =PRIMI!G216 -> 0 | C16: =13*B16 -> 0
A17: X 14 | B17: =PRIMI!G217 -> 0 | C17: =14*B17 -> 0
A18: X 15 | B18: =PRIMI!G218 -> 0 | C18: =15*B18 -> 0
A19: X 25 | B19: =PRIMI!G228 -> 1 | C19: =25*B19 -> 25
B20: TOTALE | C20: =SUM(C4:C19) -> 220

Sheet SUGO ASTICE
A1: SUGO ALL'ASTICE MEZZO (DIVISIONE IN PORZIONI)
A4: X 1 | B4: =SUGHI!C203 -> 0 | C4: =1*B4 -> 0
A5: X 2 | B5: =SUGHI!C204 -> 6 | C5: =2*B5 -> 12
A6: X 3 | B6: =SUGHI!C205 -> 7 | C6: =3*B6 -> 21
A7: X 4 | B7: =SUGHI!C206 -> 2 | C7: =4*B7 -> 8
A8: X 5 | B8: =SUGHI!C207 -> 3 | C8: =5*B8 -> 15
A9: X 6 | B9: =SUGHI!C208 -> 0 | C9: =6*B9 -> 0
A10: X 7 | B10: =SUGHI!C209 -> 1 | C10: =7*B10 -> 7
A11: X 8 | B11: =SUGHI!C210 -> 2 | C11: =8*B11 -> 16
A12: X 9 | B12: =SUGHI!C211 -> 0 | C12: =9*B12 -> 0
A13: X 10 | B13: =SUGHI!C212 -> 0 | C13: =10*B13 -> 0
A14: X 11 | B14: =SUGHI!C213 -> 0 | C14: =11*B14 -> 0
A15: X 12 | B15: =SUGHI!C214 -> 0 | C15: =12*B15 -> 0
A16: X 13 | B16: =SUGHI!C215 -> 0 | C16: =13*B16 -> 0
A17: X 14 | B17: =SUGHI!C216 -> 0 | C17: =14*B17 -> 0
A18: X 15 | B18: =SUGHI!C217 -> 0 | C18: =15*B18 -> 0
B19: TOTALE | C19: =SUM(C4:C18) -> 79

Sheet RAGU GALLINELLA
A1: RAGU' DI GALLINELLA (DIVISIONE IN PORZIONI)
A4: X 1 | B4: =SUGHI!D203 -> 1 | C4: =1*B4 -> 1
A5: X 2 | B5: =SUGHI!D204 -> 2 | C5: =2*B5 -> 4
A6: X 3 | B6: =SUGHI!D205 -> 0 | C6: =3*B6 -> 0
A7: X 4 | B7: =SUGHI!D206 -> 4 | C7: =4*B7 -> 16
A8: X 5 | B8: =SUGHI!D207 -> 1 | C8: =5*B8 -> 5
A9: X 6 | B9: =SUGHI!D208 -> 0 | C9: =6*B9 -> 0
A10: X 7 | B10: =SUGHI!D209 -> 0 | C10: =7*B10 -> 0
A11: X 8 | B11: =SUGHI!D210 -> 0 | C11: =8*B11 -> 0
A12: X 9 | B12: =SUGHI!D211 -> 0 | C12: =9*B12 -> 0
A13: X 10 | B13: =SUGHI!D212 -> 0 | C13: =10*B13 -> 0
A14: X 11 | B14: =SUGHI!D213 -> 0 | C14: =11*B14 -> 0
A15: X 12 | B15: =SUGHI!D214 -> 0 | C15: =12*B15 -> 0
A16: X 13 | B16: =SUGHI!D215 -> 0 | C16: =13*B16 -> 0
A17: X 14 | B17: =SUGHI!D216 -> 0 | C17: =14*B17 -> 0
A18: X 15 | B18: =SUGHI!D217 -> 0 | C18: =15*B18 -> 0
B19: TOTALE | C19: =SUM(C4:C18) -> 26

Sheet PESTO
A1: PESTO PISTACCHI E GAMBERI (DIVISIONE IN PORZIONI)
A4: X 1 | B4: =SUGHI!E203 -> 1 | C4: =1*B4 -> 1
A5: X 2 | B5: =SUGHI!E204 -> 2 | C5: =2*B5 -> 4
A6: X 3 | B6: =SUGHI!E205 -> 1 | C6: =3*B6 -> 3
A7: X 4 | B7: =SUGHI!E206 -> 0 | C7: =4*B7 -> 0
A8: X 5 | B8: =SUGHI!E207 -> 2 | C8: =5*B8 -> 10
A9: X 6 | B9: =SUGHI!E208 -> 0 | C9: =6*B9 -> 0
A10: X 7 | B10: =SUGHI!E209 -> 0 | C10: =7*B10 -> 0
A11: X 8 | B11: =SUGHI!E210 -> 0 | C11: =8*B11 -> 0
A12: X 9 | B12: =SUGHI!E211 -> 0 | C12: =9*B12 -> 0
A13: X 10 | B13: =SUGHI!E212 -> 0 | C13: =10*B13 -> 0
A14: X 11 | B14: =SUGHI!E213 -> 0 | C14: =11*B14 -> 0
A15: X 12 | B15: =SUGHI!E214 -> 0 | C15: =12*B15 -> 0
A16: X 13 | B16: =SUGHI!E215 -> 0 | C16: =13*B16 -> 0
A17: X 14 | B17: =SUGHI!E216 -> 0 | C17: =14*B17 -> 0
A18: X 15 | B18: =SUGHI!E217 -> 0 | C18: =15*B18 -> 0
B19: TOTALE | C19: =SUM(C4:C18) -> 18

Sheet SUGO PESCATORA
A1: SUGO ALLA PESCATORA (DIVISIONE IN PORZIONI)
A4: X 1 | B4: =SUGHI!F203 -> 0 | C4: =1*B4 -> 0
A5: X 2 | B5: =SUGHI!F204 -> 3 | C5: =2*B5 -> 6
A6: X 3 | B6: =SUGHI!F205 -> 1 | C6: =3*B6 -> 3
A7: X 4 | B7: =SUGHI!F206 -> 1 | C7: =4*B7 -> 4
A8: X 5 | B8: =SUGHI!F207 -> 5 | C8: =5*B8 -> 25
A9: X 6 | B9: =SUGHI!F208 -> 1 | C9: =6*B9 -> 6
A10: X 7 | B10: =SUGHI!F209 -> 0 | C10: =7*B10 -> 0
A11: X 8 | B11: =SUGHI!F210 -> 2 | C11: =8*B11 -> 16
A12: X 9 | B12: =SUGHI!F211 -> 1 | C12: =9*B12 -> 9
A13: X 10 | B13: =SUGHI!F212 -> 0 | C13: =10*B13 -> 0
A14: X 11 | B14: =SUGHI!F213 -> 0 | C14: =11*B14 -> 0
A15: X 12 | B15: =SUGHI!F214 -> 0 | C15: =12*B15 -> 0
A16: X 13 | B16: =SUGHI!F215 -> 0 | C16: =13*B16 -> 0
A17: X 14 | B17: =SUGHI!F216 -> 0 | C17: =14*B17 -> 0
A18: X 15 | B18: =SUGHI!F217 -> 0 | C18: =15*B18 -> 0
B19: TOTALE | C19: =SUM(C4:C18) -> 69

Sheet SPIEDINI
A1: SPIEDINI DI BRANZINO CON GAMBERI GRATINATI (DIVISIONE IN PORZIONI)
A4: X 1 | B4: ='SECONDI '!C203 -> 3 | C4: =1*B4 -> 3
A5: X 2 | B5: ='SECONDI '!C204 -> 9 | C5: =2*B5 -> 18
A6: X 3 | B6: ='SECONDI '!C205 -> 5 | C6: =3*B6 -> 15
A7: X 4 | B7: ='SECONDI '!C206 -> 3 | C7: =4*B7 -> 12
A8: X 5 | B8: ='SECONDI '!C207 -> 1 | C8: =5*B8 -> 5
A9: X 6 | B9: ='SECONDI '!C208 -> 4 | C9: =6*B9 -> 24
A10: X 7 | B10: ='SECONDI '!C209 -> 2 | C10: =7*B10 -> 14
A11: X 8 | B11: ='SECONDI '!C210 -> 2 | C11: =8*B11 -> 16
A12: X 9 | B12: ='SECONDI '!C211 -> 0 | C12: =9*B12 -> 0
A13: X 10 | B13: ='SECONDI '!C212 -> 0 | C13: =10*B13 -> 0
A14: X 11 | B14: ='SECONDI '!C213 -> 0 | C14: =11*B14 -> 0
A15: X 12 | B15: ='SECONDI '!C214 -> 1 | C15: =12*B15 -> 12
A16: X 13 | B16: ='SECONDI '!C215 -> 0 | C16: =13*B16 -> 0
A17: X 14 | B17: ='SECONDI '!C216 -> 0 | C17: =14*B17 -> 0
A18: X 15 | B18: ='SECONDI '!C217 -> 0 | C18: =15*B18 -> 0
B19: TOTALE | C19: =SUM(C4:C18) -> 119

Sheet ORATA
A1: ORATA IN CROSTA DI PATATE AL TIMO (DIVISIONE IN PORZIONI)
B3: ORDINI | C3: QUANTITA'
A4: X 1 | B4: ='SECONDI '!D203 -> 6 | C4: =1*B4 -> 6
A5: X 2 | B5: ='SECONDI '!D204 -> 7 | C5: =2*B5 -> 14
A6: X 3 | B6: ='SECONDI '!D205 -> 2 | C6: =3*B6 -> 6
A7: X 4 | B7: ='SECONDI '!D206 -> 3 | C7: =4*B7 -> 12
A8: X 5 | B8: ='SECONDI '!D207 -> 1 | C8: =5*B8 -> 5
A9: X 6 | B9: ='SECONDI '!D208 -> 4 | C9: =6*B9 -> 24
A10: X 7 | B10: ='SECONDI '!D209 -> 0 | C10: =7*B10 -> 0
A11: X 8 | B11: ='SECONDI '!D210 -> 2 | C11: =8*B11 -> 16
A12: X 9 | B12: ='SECONDI '!D211 -> 0 | C12: =9*B12 -> 0
A13: X 10 | B13: ='SECONDI '!D212 -> 0 | C13: =10*B13 -> 0
A14: X 11 | B14: ='SECONDI '!D213 -> 0 | C14: =11*B14 -> 0
A15: X 12 | B15: ='SECONDI '!D214 -> 0 | C15: =12*B15 -> 0
A16: X 13 | B16: ='SECONDI '!D215 -> 0 | C16: =13*B16 -> 0
A17: X 14 | B17: ='SECONDI '!D216 -> 0 | C17: =14*B17 -> 0
A18: X 15 | B18: ='SECONDI '!D217 -> 0 | C18: =15*B18 -> 0
B19: TOTALE | C19: =SUM(C4:C18) -> 83

Sheet BACCALA
A1: BACCALA' FRITTO (DIVISIONE IN PORZIONI)
A4: X 1 | B4: ='SECONDI '!E203 -> 3 | C4: =1*B4 -> 3
A5: X 2 | B5: ='SECONDI '!E204 -> 4 | C5: =2*B5 -> 8
A6: X 3 | B6: ='SECONDI '!E205 -> 2 | C6: =3*B6 -> 6
A7: X 4 | B7: ='SECONDI '!E206 -> 1 | C7: =4*B7 -> 4
A8: X 5 | B8: ='SECONDI '!E207 -> 0 | C8: =5*B8 -> 0
A9: X 6 | B9: ='SECONDI '!E208 -> 0 | C9: =6*B9 -> 0
A10: X 7 | B10: ='SECONDI '!E209 -> 0 | C10: =7*B10 -> 0
A11: X 8 | B11: ='SECONDI '!E210 -> 0 | C11: =8*B11 -> 0
A12: X 9 | B12: ='SECONDI '!E211 -> 0 | C12: =9*B12 -> 0
A13: X 10 | B13: ='SECONDI '!E212 -> 0 | C13: =10*B13 -> 0
A14: X 11 | B14: ='SECONDI '!E213 -> 0 | C14: =11*B14 -> 0
A15: X 12 | B15: ='SECONDI '!E214 -> 0 | C15: =12*B15 -> 0
A16: X 13 | B16: ='SECONDI '!E215 -> 0 | C16: =13*B16 -> 0
A17: X 14 | B17: ='SECONDI '!E216 -> 0 | C17: =14*B17 -> 0
A18: X 15 | B18: ='SECONDI '!E217 -> 0 | C18: =15*B18 -> 0
B19: TOTALE | C19: =SUM(C4:C18) -> 21

Sheet BRANZINO
A1: FILETTO DI BRANZINO IN CROSTA DI PISTACCHI E ZENZERO (DIVISIONE IN PORZIONI)
A4: X 1 | B4: ='SECONDI '!F203 -> 4 | C4: =1*B4 -> 4
A5: X 2 | B5: ='SECONDI '!F204 -> 6 | C5: =2*B5 -> 12
A6: X 3 | B6: ='SECONDI '!F205 -> 1 | C6: =3*B6 -> 3
A7: X 4 | B7: ='SECONDI '!F206 -> 1 | C7: =4*B7 -> 4
A8: X 5 | B8: ='SECONDI '!F207 -> 0 | C8: =5*B8 -> 0
A9: X 6 | B9: ='SECONDI '!F208 -> 0 | C9: =6*B9 -> 0
A10: X 7 | B10: ='SECONDI '!F209 -> 0 | C10: =7*B10 -> 0
A11: X 8 | B11: ='SECONDI '!F210 -> 0 | C11: =8*B11 -> 0
A12: X 9 | B12: ='SECONDI '!F211 -> 0 | C12: =9*B12 -> 0
A13: X 10 | B13: ='SECONDI '!F212 -> 0 | C13: =10*B13 -> 0
A14: X 11 | B14: ='SECONDI '!F213 -> 0 | C14: =11*B14 -> 0
A15: X 12 | B15: ='SECONDI '!F214 -> 0 | C15: =12*B15 -> 0
A16: X 13 | B16: ='SECONDI '!F215 -> 0 | C16: =13*B16 -> 0
A17: X 14 | B17: ='SECONDI '!F216 -> 0 | C17: =14*B17 -> 0
A18: X 15 | B18: ='SECONDI '!F217 -> 0 | C18: =15*B18 -> 0
B19: TOTALE | C19: =SUM(C4:C18) -> 23

Sheet SALMONE
A1: SALMONE PROFUMATO AL LIMONE E TIMO (DIVISIONE IN PORZIONI)
A4: X 1 | B4: ='SECONDI '!G203 -> 1 | C4: =1*B4 -> 1
A5: X 2 | B5: ='SECONDI '!G204 -> 1 | C5: =2*B5 -> 2
A6: X 3 | B6: ='SECONDI '!G205 -> 0 | C6: =3*B6 -> 0
A7: X 4 | B7: ='SECONDI '!G206 -> 0 | C7: =4*B7 -> 0
A8: X 5 | B8: ='SECONDI '!G207 -> 0 | C8: =5*B8 -> 0
A9: X 6 | B9: ='SECONDI '!G208 -> 0 | C9: =6*B9 -> 0
A10: X 7 | B10: ='SECONDI '!G209 -> 0 | C10: =7*B10 -> 0
A11: X 8 | B11: ='SECONDI '!G210 -> 0 | C11: =8*B11 -> 0
A12: X 9 | B12: ='SECONDI '!G211 -> 0 | C12: =9*B12 -> 0
A13: X 10 | B13: ='SECONDI '!G212 -> 0 | C13: =10*B13 -> 0
A14: X 11 | B14: ='SECONDI '!G213 -> 0 | C14: =11*B14 -> 0
A15: X 12 | B15: ='SECONDI '!G214 -> 0 | C15: =12*B15 -> 0
A16: X 13 | B16: ='SECONDI '!G215 -> 0 | C16: =13*B16 -> 0
A17: X 14 | B17: ='SECONDI '!G216 -> 0 | C17: =14*B17 -> 0
A18: X 15 | B18: ='SECONDI '!G217 -> 0 | C18: =15*B18 -> 0
B19: TOTALE | C19: =SUM(C4:C18) -> 3

Sheet EXTRA SUGHI 1
A1: POLIPETTI IN UMIDO (DIVISIONE IN PORZIONI)
A4: X 1 | B4: =SUGHI!G203 -> 0 | C4: =1*B4 -> 0
A5: X 2 | B5: =SUGHI!G204 -> 0 | C5: =2*B5 -> 0
A6: X 3 | B6: =SUGHI!G205 -> 0 | C6: =3*B6 -> 0
A7: X 4 | B7: =SUGHI!G206 -> 0 | C7: =4*B7 -> 0
A8: X 5 | B8: =SUGHI!G207 -> 0 | C8: =5*B8 -> 0
A9: X 6 | B9: =SUGHI!G208 -> 0 | C9: =6*B9 -> 0
A10: X 7 | B10: =SUGHI!G209 -> 0 | C10: =7*B10 -> 0
A11: X 8 | B11: =SUGHI!G210 -> 0 | C11: =8*B11 -> 0
A12: X 9 | B12: =SUGHI!G211 -> 0 | C12: =9*B12 -> 0
A13: X 10 | B13: =SUGHI!G212 -> 0 | C13: =10*B13 -> 0
A14: X 11 | B14: =SUGHI!G213 -> 0 | C14: =11*B14 -> 0
A15: X 12 | B15: =SUGHI!G214 -> 0 | C15: =12*B15 -> 0
A16: X 13 | B16: =SUGHI!G215 -> 0 | C16: =13*B16 -> 0
A17: X 14 | B17: =SUGHI!G216 -> 0 | C17: =14*B17 -> 0
A18: X 15 | B18: =SUGHI!G217 -> 0 | C18: =15*B18 -> 0
A19: X 16 | B19: =SUGHI!G218 -> 0 | C19: =16*B19 -> 0
A20: X 17 | B20: =SUGHI!G219 -> 0 | C20: =17*B20 -> 0
A21: X 18 | B21: =SUGHI!G220 -> 0 | C21: =18*B21 -> 0
A22: X 19 | B22: =SUGHI!G221 -> 0 | C22: =19*B22 -> 0
A23: X 20 | B23: =SUGHI!G222 -> 0 | C23: =20*B23 -> 0
A24: X 21 | B24: =SUGHI!G223 -> 0 | C24: =21*B24 -> 0
A25: X 22 | B25: =SUGHI!G224 -> 0 | C25: =22*B25 -> 0
A26: X 23 | B26: =SUGHI!G225 -> 0 | C26: =23*B26 -> 0
A27: X 24 | B27: =SUGHI!G226 -> 0 | C27: =24*B27 -> 0
A28: X 25 | B28: =SUGHI!G227 -> 0 | C28: =25*B28 -> 0
B29: TOTALE | C29: =SUM(C4:C28) -> 0

Sheet EXTRA SUGHI 2
A1: RAGU' DI MARE (DIVISIONE IN PORZIONI)
A4: X 1 | B4: =SUGHI!H203 -> 0 | C4: =1*B4 -> 0
A5: X 2 | B5: =SUGHI!H204 -> 0 | C5: =2*B5 -> 0
A6: X 3 | B6: =SUGHI!H205 -> 0 | C6: =3*B6 -> 0
A7: X 4 | B7: =SUGHI!H206 -> 0 | C7: =4*B7 -> 0
A8: X 5 | B8: =SUGHI!H207 -> 0 | C8: =5*B8 -> 0
A9: X 6 | B9: =SUGHI!H208 -> 0 | C9: =6*B9 -> 0
A10: X 7 | B10: =SUGHI!H209 -> 0 | C10: =7*B10 -> 0
A11: X 8 | B11: =SUGHI!H210 -> 0 | C11: =8*B11 -> 0
A12: X 9 | B12: =SUGHI!H211 -> 0 | C12: =9*B12 -> 0
A13: X 10 | B13: =SUGHI!H212 -> 0 | C13: =10*B13 -> 0
A14: X 11 | B14: =SUGHI!H213 -> 0 | C14: =11*B14 -> 0
A15: X 12 | B15: =SUGHI!H214 -> 0 | C15: =12*B15 -> 0
A16: X 13 | B16: =SUGHI!H215 -> 0 | C16: =13*B16 -> 0
A17: X 14 | B17: =SUGHI!H216 -> 0 | C17: =14*B17 -> 0
A18: X 15 | B18: =SUGHI!H217 -> 0 | C18: =15*B18 -> 0
A19: X 16 | B19: =SUGHI!H218 -> 0 | C19: =16*B19 -> 0
A20: X 17 | B20: =SUGHI!H219 -> 0 | C20: =17*B20 -> 0
A21: X 18 | B21: =SUGHI!H220 -> 0 | C21: =18*B21 -> 0
A22: X 19 | B22: =SUGHI!H221 -> 0 | C22: =19*B22 -> 0
A23: X 20 | B23: =SUGHI!H222 -> 0 | C23: =20*B23 -> 0
A24: X 21 | B24: =SUGHI!H223 -> 0 | C24: =21*B24 -> 0
A25: X 22 | B25: =SUGHI!H224 -> 0 | C25: =22*B25 -> 0
A26: X 23 | B26: =SUGHI!H225 -> 0 | C26: =23*B26 -> 0
A27: X 24 | B27: =SUGHI!H226 -> 0 | C27: =24*B27 -> 0
A28: X 25 | B28: =SUGHI!H227 -> 0 | C28: =25*B28 -> 0
B29: TOTALE | C29: =SUM(C4:C28) -> 0

Sheet EXTRA SECONDI
A1: TONNO TONNATO (DIVISIONE IN PORZIONI)
A4: X 1 | B4: ='SECONDI '!H203 -> 0 | C4: =1*B4 -> 0
A5: X 2 | B5: ='SECONDI '!H204 -> 0 | C5: =2*B5 -> 0
A6: X 3 | B6: ='SECONDI '!H205 -> 0 | C6: =3*B6 -> 0
A7: X 4 | B7: ='SECONDI '!H206 -> 0 | C7: =4*B7 -> 0
A8: X 5 | B8: ='SECONDI '!H207 -> 0 | C8: =5*B8 -> 0
A9: X 6 | B9: ='SECONDI '!H208 -> 0 | C9: =6*B9 -> 0
A10: X 7 | B10: ='SECONDI '!H209 -> 0 | C10: =7*B10 -> 0
A11: X 8 | B11: ='SECONDI '!H210 -> 0 | C11: =8*B11 -> 0
A12: X 9 | B12: ='SECONDI '!H211 -> 0 | C12: =9*B12 -> 0
A13: X 10 | B13: ='SECONDI '!H212 -> 0 | C13: =10*B13 -> 0
A14: X 11 | B14: ='SECONDI '!H213 -> 0 | C14: =11*B14 -> 0
A15: X 12 | B15: ='SECONDI '!H214 -> 0 | C15: =12*B15 -> 0
A16: X 13 | B16: ='SECONDI '!H215 -> 0 | C16: =13*B16 -> 0
A17: X 14 | B17: ='SECONDI '!H216 -> 0 | C17: =14*B17 -> 0
A18: X 15 | B18: ='SECONDI '!H217 -> 0 | C18: =15*B18 -> 0
A19: X 16 | B19: ='SECONDI '!H218 -> 0 | C19: =16*B19 -> 0
A20: X 17 | B20: ='SECONDI '!H219 -> 0 | C20: =17*B20 -> 0
A21: X 18 | B21: ='SECONDI '!H220 -> 0 | C21: =18*B21 -> 0
A22: X 19 | B22: ='SECONDI '!H221 -> 0 | C22: =19*B22 -> 0
A23: X 20 | B23: ='SECONDI '!H222 -> 0 | C23: =20*B23 -> 0
A24: X 21 | B24: ='SECONDI '!H223 -> 0 | C24: =21*B24 -> 0
A25: X 22 | B25: ='SECONDI '!H224 -> 0 | C25: =22*B25 -> 0
A26: X 23 | B26: ='SECONDI '!H225 -> 0 | C26: =23*B26 -> 0
A27: X 24 | B27: ='SECONDI '!H226 -> 0 | C27: =24*B27 -> 0
A28: X 25 | B28: ='SECONDI '!H227 -> 0 | C28: =25*B28 -> 0
B29: TOTALE | C29: =SUM(C4:C28) -> 0
